Workbook

Sheet In_GIAO NHAN BAI
A1: SỞ GD&ĐT TP HỒ CHÍ MINH | J1: CỘNG HÒA XÃ HỘI CHỦ NGHĨA VIỆT NAM | S1: K10 | T1: K11 | U1: K12 | V1: KT | W1: VH
A2: TRUNG TÂM GDNN - GDTX THỦ ĐỨC | J2: Độc lập - Tự do - Hạnh phúc | Q2: KH/PHÒNG | R2: TỪ | S2: 1 | T2: 18 | U2: 36 | V2: 62 | W2: 83
A3: DANH SÁCH GIAO NHẬN BÀI KIỂM TRA CUỐI HỌC KỲ I - NH 2025-2026 | P3: 54 | R3: ĐẾN | S3: 17 | T3: 35 | U3: 61 | V3: 82 | W3: 114
A4: =VLOOKUP(P3,TH_P.thi!$A$18:$T$165,20,0) -> NGÀY THI: 22+24/12/2025 | I4: =VLOOKUP($P$3,TH_P.thi!$A$18:$T$165,19,0) -> TỔ HỢP 5 (12AS9,10,11,12) | M4: PHÒNG THI: | O4: =VLOOKUP($P$3,$S$7:$U$42,2,0) -> 7B | P4: =VLOOKUP($P$3,$S$7:$U$42,3,0) -> 7B.S2
A6: Stt | B6: Phòng thi | C6: SBD | D6: Họ và | E6: tên | F6: Lớp | G6: Ghi chú | H6: MÔN THI | P6: Nghỉ học (NgiH) | R6: Stt | S6: KH/phòng | T6: Phòng
H7: =VLOOKUP($P3,TH_P.thi!$A$18:$T$165,13,0) -> VĂN | J7: =VLOOKUP($P3,TH_P.thi!$A$18:$T$165,14,0) -> KT-PL | L7: =VLOOKUP($P3,TH_P.thi!$A$18:$T$165,15,0) -> TOÁN | N7: =VLOOKUP($P3,TH_P.thi!$A$18:$T$165,16,0) -> SỬ | R7: 1 | S7: 36 | T7: =IFERROR(VLOOKUP($S7,TH_P.thi!$A$18:$P$165,3,0),0) -> 1A | U7: =IFERROR(VLOOKUP($S7,TH_P.thi!$A$18:$T$165,6,0),0) -> 1A.S2
H8: Số tờ | I8: Ký tên | J8: Mã đề | K8: Ký tên | L8: Mã đề | M8: Ký tên | N8: Mã đề | O8: Ký tên | R8: 2 | S8: =S7+1 -> 37 | T8: =IFERROR(VLOOKUP($S8,TH_P.thi!$A$18:$P$165,3,0),0) -> 2A | U8: =IFERROR(VLOOKUP($S8,TH_P.thi!$A$18:$T$165,6,0),0) -> 2A.S2
A9: 1 | B9: {=IFERROR(INDEX('DS_Tong_12AS-AT-VH'!$A$9:$I$3045,MATCH(1,($A9='DS_Tong_12AS-AT-VH'!$A$9:$A$3045)*($P$4='DS_Tong_12AS-AT-VH'!$B$9:$B$3045),0),4),0)} -> P.7B | C9: {=IFERROR(INDEX('DS_Tong_12AS-AT-VH'!$A$9:$I$3045,MATCH(1,($A9='DS_Tong_12AS-AT-VH'!$A$9:$A$3045)*($P$4='DS_Tong_12AS-AT-VH'!$B$9:$B$3045),0),5),0)} -> 101418 | D9: {=IFERROR(INDEX('DS_Tong_12AS-AT-VH'!$A$9:$I$3045,MATCH(1,($A9='DS_Tong_12AS-AT-VH'!$A$9:$A$3045)*($P$4='DS_Tong_12AS-AT-VH'!$B$9:$B$3045),0),6),0)} -> Võ Ái | E9: {=IFERROR(INDEX('DS_Tong_12AS-AT-VH'!$A$9:$I$3045,MATCH(1,($A9='DS_Tong_12AS-AT-VH'!$A$9:$A$3045)*($P$4='DS_Tong_12AS-AT-VH'!$B$9:$B$3045),0),7),0)} -> Nhi | F9: {=IFERROR(INDEX('DS_Tong_12AS-AT-VH'!$A$9:$I$3045,MATCH(1,($A9='DS_Tong_12AS-AT-VH'!$A$9:$A$3045)*($P$4='DS_Tong_12AS-AT-VH'!$B$9:$B$3045),0),8),0)} -> 12AS10 | G9: {=IFERROR(INDEX('DS_Tong_12AS-AT-VH'!$A$9:$I$3045,MATCH(1,($A9='DS_Tong_12AS-AT-VH'!$A$9:$A$3045)*($P$4='DS_Tong_12AS-AT-VH'!$B$9:$B$3045),0),9),0)} -> 0 | P9: {=IFERROR(VLOOKUP($C9,'DS_Tong_12AS-AT-VH'!$E$9:$S$3024,13,0),0)} -> 0 | R9: 3 | S9: =S8+1 -> 38 | T9: =IFERROR(VLOOKUP($S9,TH_P.thi!$A$18:$P$165,3,0),0) -> 3A | U9: =IFERROR(VLOOKUP($S9,TH_P.thi!$A$18:$T$165,6,0),0) -> 3A.S2
A10: 2 | B10: {=IFERROR(INDEX('DS_Tong_12AS-AT-VH'!$A$9:$I$3045,MATCH(1,($A10='DS_Tong_12AS-AT-VH'!$A$9:$A$3045)*($P$4='DS_Tong_12AS-AT-VH'!$B$9:$B$3045),0),4),0)} -> P.7B | C10: {=IFERROR(INDEX('DS_Tong_12AS-AT-VH'!$A$9:$I$3045,MATCH(1,($A10='DS_Tong_12AS-AT-VH'!$A$9:$A$3045)*($P$4='DS_Tong_12AS-AT-VH'!$B$9:$B$3045),0),5),0)} -> 101419 | D10: {=IFERROR(INDEX('DS_Tong_12AS-AT-VH'!$A$9:$I$3045,MATCH(1,($A10='DS_Tong_12AS-AT-VH'!$A$9:$A$3045)*($P$4='DS_Tong_12AS-AT-VH'!$B$9:$B$3045),0),6),0)} -> Hoàng Thị Ngọc | E10: {=IFERROR(INDEX('DS_Tong_12AS-AT-VH'!$A$9:$I$3045,MATCH(1,($A10='DS_Tong_12AS-AT-VH'!$A$9:$A$3045)*($P$4='DS_Tong_12AS-AT-VH'!$B$9:$B$3045),0),7),0)} -> Nhung | F10: {=IFERROR(INDEX('DS_Tong_12AS-AT-VH'!$A$9:$I$3045,MATCH(1,($A10='DS_Tong_12AS-AT-VH'!$A$9:$A$3045)*($P$4='DS_Tong_12AS-AT-VH'!$B$9:$B$3045),0),8),0)} -> 12AS9 | G10: {=IFERROR(INDEX('DS_Tong_12AS-AT-VH'!$A$9:$I$3045,MATCH(1,($A10='DS_Tong_12AS-AT-VH'!$A$9:$A$3045)*($P$4='DS_Tong_12AS-AT-VH'!$B$9:$B$3045),0),9),0)} -> 0 | P10: =IFERROR(VLOOKUP($C10,'DS_Tong_12AS-AT-VH'!$E$9:$S$3024,13,0),0) -> 0 | R10: 4 | S10: =S9+1 -> 39 | T10: =IFERROR(VLOOKUP($S10,TH_P.thi!$A$18:$P$165,3,0),0) -> 4A | U10: =IFERROR(VLOOKUP($S10,TH_P.thi!$A$18:$T$165,6,0),0) -> 4A.S2
A11: 3 | B11: {=IFERROR(INDEX('DS_Tong_12AS-AT-VH'!$A$9:$I$3045,MATCH(1,($A11='DS_Tong_12AS-AT-VH'!$A$9:$A$3045)*($P$4='DS_Tong_12AS-AT-VH'!$B$9:$B$3045),0),4),0)} -> P.7B | C11: {=IFERROR(INDEX('DS_Tong_12AS-AT-VH'!$A$9:$I$3045,MATCH(1,($A11='DS_Tong_12AS-AT-VH'!$A$9:$A$3045)*($P$4='DS_Tong_12AS-AT-VH'!$B$9:$B$3045),0),5),0)} -> 101420 | D11: {=IFERROR(INDEX('DS_Tong_12AS-AT-VH'!$A$9:$I$3045,MATCH(1,($A11='DS_Tong_12AS-AT-VH'!$A$9:$A$3045)*($P$4='DS_Tong_12AS-AT-VH'!$B$9:$B$3045),0),6),0)} -> Hoàng Huỳnh | E11: {=IFERROR(INDEX('DS_Tong_12AS-AT-VH'!$A$9:$I$3045,MATCH(1,($A11='DS_Tong_12AS-AT-VH'!$A$9:$A$3045)*($P$4='DS_Tong_12AS-AT-VH'!$B$9:$B$3045),0),7),0)} -> Như | F11: {=IFERROR(INDEX('DS_Tong_12AS-AT-VH'!$A$9:$I$3045,MATCH(1,($A11='DS_Tong_12AS-AT-VH'!$A$9:$A$3045)*($P$4='DS_Tong_12AS-AT-VH'!$B$9:$B$3045),0),8),0)} -> 12AS10 | G11: {=IFERROR(INDEX('DS_Tong_12AS-AT-VH'!$A$9:$I$3045,MATCH(1,($A11='DS_Tong_12AS-AT-VH'!$A$9:$A$3045)*($P$4='DS_Tong_12AS-AT-VH'!$B$9:$B$3045),0),9),0)} -> 0 | P11: =IFERROR(VLOOKUP($C11,'DS_Tong_12AS-AT-VH'!$E$9:$S$3024,13,0),0) -> 0 | R11: 5 | S11: =S10+1 -> 40 | T11: =IFERROR(VLOOKUP($S11,TH_P.thi!$A$18:$P$165,3,0),0) -> 5A | U11: =IFERROR(VLOOKUP($S11,TH_P.thi!$A$18:$T$165,6,0),0) -> 5A.S2
A12: 4 | B12: {=IFERROR(INDEX('DS_Tong_12AS-AT-VH'!$A$9:$I$3045,MATCH(1,($A12='DS_Tong_12AS-AT-VH'!$A$9:$A$3045)*($P$4='DS_Tong_12AS-AT-VH'!$B$9:$B$3045),0),4),0)} -> P.7B | C12: {=IFERROR(INDEX('DS_Tong_12AS-AT-VH'!$A$9:$I$3045,MATCH(1,($A12='DS_Tong_12AS-AT-VH'!$A$9:$A$3045)*($P$4='DS_Tong_12AS-AT-VH'!$B$9:$B$3045),0),5),0)} -> 101421 | D12: {=IFERROR(INDEX('DS_Tong_12AS-AT-VH'!$A$9:$I$3045,MATCH(1,($A12='DS_Tong_12AS-AT-VH'!$A$9:$A$3045)*($P$4='DS_Tong_12AS-AT-VH'!$B$9:$B$3045),0),6),0)} -> Nguyễn Ngọc Bảo | E12: {=IFERROR(INDEX('DS_Tong_12AS-AT-VH'!$A$9:$I$3045,MATCH(1,($A12='DS_Tong_12AS-AT-VH'!$A$9:$A$3045)*($P$4='DS_Tong_12AS-AT-VH'!$B$9:$B$3045),0),7),0)} -> Như | F12: {=IFERROR(INDEX('DS_Tong_12AS-AT-VH'!$A$9:$I$3045,MATCH(1,($A12='DS_Tong_12AS-AT-VH'!$A$9:$A$3045)*($P$4='DS_Tong_12AS-AT-VH'!$B$9:$B$3045),0),8),0)} -> 12AS10 | G12: {=IFERROR(INDEX('DS_Tong_12AS-AT-VH'!$A$9:$I$3045,MATCH(1,($A12='DS_Tong_12AS-AT-VH'!$A$9:$A$3045)*($P$4='DS_Tong_12AS-AT-VH'!$B$9:$B$3045),0),9),0)} -> 0 | P12: =IFERROR(VLOOKUP($C12,'DS_Tong_12AS-AT-VH'!$E$9:$S$3024,13,0),0) -> 0 | R12: 6 | S12: =S11+1 -> 41 | T12: =IFERROR(VLOOKUP($S12,TH_P.thi!$A$18:$P$165,3,0),0) -> 6A | U12: =IFERROR(VLOOKUP($S12,TH_P.thi!$A$18:$T$165,6,0),0) -> 6A.S2
A13: 5 | B13: {=IFERROR(INDEX('DS_Tong_12AS-AT-VH'!$A$9:$I$3045,MATCH(1,($A13='DS_Tong_12AS-AT-VH'!$A$9:$A$3045)*($P$4='DS_Tong_12AS-AT-VH'!$B$9:$B$3045),0),4),0)} -> P.7B | C13: {=IFERROR(INDEX('DS_Tong_12AS-AT-VH'!$A$9:$I$3045,MATCH(1,($A13='DS_Tong_12AS-AT-VH'!$A$9:$A$3045)*($P$4='DS_Tong_12AS-AT-VH'!$B$9:$B$3045),0),5),0)} -> 101422 | D13: {=IFERROR(INDEX('DS_Tong_12AS-AT-VH'!$A$9:$I$3045,MATCH(1,($A13='DS_Tong_12AS-AT-VH'!$A$9:$A$3045)*($P$4='DS_Tong_12AS-AT-VH'!$B$9:$B$3045),0),6),0)} -> Nguyễn Ngọc Tâm | E13: {=IFERROR(INDEX('DS_Tong_12AS-AT-VH'!$A$9:$I$3045,MATCH(1,($A13='DS_Tong_12AS-AT-VH'!$A$9:$A$3045)*($P$4='DS_Tong_12AS-AT-VH'!$B$9:$B$3045),0),7),0)} -> Như | F13: {=IFERROR(INDEX('DS_Tong_12AS-AT-VH'!$A$9:$I$3045,MATCH(1,($A13='DS_Tong_12AS-AT-VH'!$A$9:$A$3045)*($P$4='DS_Tong_12AS-AT-VH'!$B$9:$B$3045),0),8),0)} -> 12AS12 | G13: {=IFERROR(INDEX('DS_Tong_12AS-AT-VH'!$A$9:$I$3045,MATCH(1,($A13='DS_Tong_12AS-AT-VH'!$A$9:$A$3045)*($P$4='DS_Tong_12AS-AT-VH'!$B$9:$B$3045),0),9),0)} -> 0 | P13: =IFERROR(VLOOKUP($C13,'DS_Tong_12AS-AT-VH'!$E$9:$S$3024,13,0),0) -> 0 | R13: 7 | S13: =S12+1 -> 42 | T13: =IFERROR(VLOOKUP($S13,TH_P.thi!$A$18:$P$165,3,0),0) -> 7A | U13: =IFERROR(VLOOKUP($S13,TH_P.thi!$A$18:$T$165,6,0),0) -> 7A.S2
A14: 6 | B14: {=IFERROR(INDEX('DS_Tong_12AS-AT-VH'!$A$9:$I$3045,MATCH(1,($A14='DS_Tong_12AS-AT-VH'!$A$9:$A$3045)*($P$4='DS_Tong_12AS-AT-VH'!$B$9:$B$3045),0),4),0)} -> P.7B | C14: {=IFERROR(INDEX('DS_Tong_12AS-AT-VH'!$A$9:$I$3045,MATCH(1,($A14='DS_Tong_12AS-AT-VH'!$A$9:$A$3045)*($P$4='DS_Tong_12AS-AT-VH'!$B$9:$B$3045),0),5),0)} -> 101423 | D14: {=IFERROR(INDEX('DS_Tong_12AS-AT-VH'!$A$9:$I$3045,MATCH(1,($A14='DS_Tong_12AS-AT-VH'!$A$9:$A$3045)*($P$4='DS_Tong_12AS-AT-VH'!$B$9:$B$3045),0),6),0)} -> Nguyễn Ngọc Tố | E14: {=IFERROR(INDEX('DS_Tong_12AS-AT-VH'!$A$9:$I$3045,MATCH(1,($A14='DS_Tong_12AS-AT-VH'!$A$9:$A$3045)*($P$4='DS_Tong_12AS-AT-VH'!$B$9:$B$3045),0),7),0)} -> Như | F14: {=IFERROR(INDEX('DS_Tong_12AS-AT-VH'!$A$9:$I$3045,MATCH(1,($A14='DS_Tong_12AS-AT-VH'!$A$9:$A$3045)*($P$4='DS_Tong_12AS-AT-VH'!$B$9:$B$3045),0),8),0)} -> 12AS11 | G14: {=IFERROR(INDEX('DS_Tong_12AS-AT-VH'!$A$9:$I$3045,MATCH(1,($A14='DS_Tong_12AS-AT-VH'!$A$9:$A$3045)*($P$4='DS_Tong_12AS-AT-VH'!$B$9:$B$3045),0),9),0)} -> 0 | P14: =IFERROR(VLOOKUP($C14,'DS_Tong_12AS-AT-VH'!$E$9:$S$3024,13,0),0) -> 0 | R14: 8 | S14: =S13+1 -> 43 | T14: =IFERROR(VLOOKUP($S14,TH_P.thi!$A$18:$P$165,3,0),0) -> 9A | U14: =IFERROR(VLOOKUP($S14,TH_P.thi!$A$18:$T$165,6,0),0) -> 9A.S2
A15: 7 | B15: {=IFERROR(INDEX('DS_Tong_12AS-AT-VH'!$A$9:$I$3045,MATCH(1,($A15='DS_Tong_12AS-AT-VH'!$A$9:$A$3045)*($P$4='DS_Tong_12AS-AT-VH'!$B$9:$B$3045),0),4),0)} -> P.7B | C15: {=IFERROR(INDEX('DS_Tong_12AS-AT-VH'!$A$9:$I$3045,MATCH(1,($A15='DS_Tong_12AS-AT-VH'!$A$9:$A$3045)*($P$4='DS_Tong_12AS-AT-VH'!$B$9:$B$3045),0),5),0)} -> 101424 | D15: {=IFERROR(INDEX('DS_Tong_12AS-AT-VH'!$A$9:$I$3045,MATCH(1,($A15='DS_Tong_12AS-AT-VH'!$A$9:$A$3045)*($P$4='DS_Tong_12AS-AT-VH'!$B$9:$B$3045),0),6),0)} -> Nguyễn Trương Yến | E15: {=IFERROR(INDEX('DS_Tong_12AS-AT-VH'!$A$9:$I$3045,MATCH(1,($A15='DS_Tong_12AS-AT-VH'!$A$9:$A$3045)*($P$4='DS_Tong_12AS-AT-VH'!$B$9:$B$3045),0),7),0)} -> Như | F15: {=IFERROR(INDEX('DS_Tong_12AS-AT-VH'!$A$9:$I$3045,MATCH(1,($A15='DS_Tong_12AS-AT-VH'!$A$9:$A$3045)*($P$4='DS_Tong_12AS-AT-VH'!$B$9:$B$3045),0),8),0)} -> 12AS12 | G15: {=IFERROR(INDEX('DS_Tong_12AS-AT-VH'!$A$9:$I$3045,MATCH(1,($A15='DS_Tong_12AS-AT-VH'!$A$9:$A$3045)*($P$4='DS_Tong_12AS-AT-VH'!$B$9:$B$3045),0),9),0)} -> 0 | P15: =IFERROR(VLOOKUP($C15,'DS_Tong_12AS-AT-VH'!$E$9:$S$3024,13,0),0) -> 0 | R15: 9 | S15: =S14+1 -> 44 | T15: =IFERROR(VLOOKUP($S15,TH_P.thi!$A$18:$P$165,3,0),0) -> 10A | U15: =IFERROR(VLOOKUP($S15,TH_P.thi!$A$18:$T$165,6,0),0) -> 10A.S2
A16: 8 | B16: {=IFERROR(INDEX('DS_Tong_12AS-AT-VH'!$A$9:$I$3045,MATCH(1,($A16='DS_Tong_12AS-AT-VH'!$A$9:$A$3045)*($P$4='DS_Tong_12AS-AT-VH'!$B$9:$B$3045),0),4),0)} -> P.7B | C16: {=IFERROR(INDEX('DS_Tong_12AS-AT-VH'!$A$9:$I$3045,MATCH(1,($A16='DS_Tong_12AS-AT-VH'!$A$9:$A$3045)*($P$4='DS_Tong_12AS-AT-VH'!$B$9:$B$3045),0),5),0)} -> 101425 | D16: {=IFERROR(INDEX('DS_Tong_12AS-AT-VH'!$A$9:$I$3045,MATCH(1,($A16='DS_Tong_12AS-AT-VH'!$A$9:$A$3045)*($P$4='DS_Tong_12AS-AT-VH'!$B$9:$B$3045),0),6),0)} -> Trần Quỳnh | E16: {=IFERROR(INDEX('DS_Tong_12AS-AT-VH'!$A$9:$I$3045,MATCH(1,($A16='DS_Tong_12AS-AT-VH'!$A$9:$A$3045)*($P$4='DS_Tong_12AS-AT-VH'!$B$9:$B$3045),0),7),0)} -> Như | F16: {=IFERROR(INDEX('DS_Tong_12AS-AT-VH'!$A$9:$I$3045,MATCH(1,($A16='DS_Tong_12AS-AT-VH'!$A$9:$A$3045)*($P$4='DS_Tong_12AS-AT-VH'!$B$9:$B$3045),0),8),0)} -> 12AS12 | G16: {=IFERROR(INDEX('DS_Tong_12AS-AT-VH'!$A$9:$I$3045,MATCH(1,($A16='DS_Tong_12AS-AT-VH'!$A$9:$A$3045)*($P$4='DS_Tong_12AS-AT-VH'!$B$9:$B$3045),0),9),0)} -> 0 | P16: =IFERROR(VLOOKUP($C16,'DS_Tong_12AS-AT-VH'!$E$9:$S$3024,13,0),0) -> 0 | R16: 10 | S16: =S15+1 -> 45 | T16: =IFERROR(VLOOKUP($S16,TH_P.thi!$A$18:$P$165,3,0),0) -> 11A | U16: =IFERROR(VLOOKUP($S16,TH_P.thi!$A$18:$T$165,6,0),0) -> 11A.S2
A17: 9 | B17: {=IFERROR(INDEX('DS_Tong_12AS-AT-VH'!$A$9:$I$3045,MATCH(1,($A17='DS_Tong_12AS-AT-VH'!$A$9:$A$3045)*($P$4='DS_Tong_12AS-AT-VH'!$B$9:$B$3045),0),4),0)} -> P.7B | C17: {=IFERROR(INDEX('DS_Tong_12AS-AT-VH'!$A$9:$I$3045,MATCH(1,($A17='DS_Tong_12AS-AT-VH'!$A$9:$A$3045)*($P$4='DS_Tong_12AS-AT-VH'!$B$9:$B$3045),0),5),0)} -> 101426 | D17: {=IFERROR(INDEX('DS_Tong_12AS-AT-VH'!$A$9:$I$3045,MATCH(1,($A17='DS_Tong_12AS-AT-VH'!$A$9:$A$3045)*($P$4='DS_Tong_12AS-AT-VH'!$B$9:$B$3045),0),6),0)} -> Vũ Thị Quỳnh | E17: {=IFERROR(INDEX('DS_Tong_12AS-AT-VH'!$A$9:$I$3045,MATCH(1,($A17='DS_Tong_12AS-AT-VH'!$A$9:$A$3045)*($P$4='DS_Tong_12AS-AT-VH'!$B$9:$B$3045),0),7),0)} -> Như | F17: {=IFERROR(INDEX('DS_Tong_12AS-AT-VH'!$A$9:$I$3045,MATCH(1,($A17='DS_Tong_12AS-AT-VH'!$A$9:$A$3045)*($P$4='DS_Tong_12AS-AT-VH'!$B$9:$B$3045),0),8),0)} -> 12AS11 | G17: {=IFERROR(INDEX('DS_Tong_12AS-AT-VH'!$A$9:$I$3045,MATCH(1,($A17='DS_Tong_12AS-AT-VH'!$A$9:$A$3045)*($P$4='DS_Tong_12AS-AT-VH'!$B$9:$B$3045),0),9),0)} -> 0 | P17: =IFERROR(VLOOKUP($C17,'DS_Tong_12AS-AT-VH'!$E$9:$S$3024,13,0),0) -> 0 | R17: 11 | S17: =S16+1 -> 46 | T17: =IFERROR(VLOOKUP($S17,TH_P.thi!$A$18:$P$165,3,0),0) -> 12A | U17: =IFERROR(VLOOKUP($S17,TH_P.thi!$A$18:$T$165,6,0),0) -> 12A.S2
A18: 10 | B18: {=IFERROR(INDEX('DS_Tong_12AS-AT-VH'!$A$9:$I$3045,MATCH(1,($A18='DS_Tong_12AS-AT-VH'!$A$9:$A$3045)*($P$4='DS_Tong_12AS-AT-VH'!$B$9:$B$3045),0),4),0)} -> P.7B | C18: {=IFERROR(INDEX('DS_Tong_12AS-AT-VH'!$A$9:$I$3045,MATCH(1,($A18='DS_Tong_12AS-AT-VH'!$A$9:$A$3045)*($P$4='DS_Tong_12AS-AT-VH'!$B$9:$B$3045),0),5),0)} -> 101427 | D18: {=IFERROR(INDEX('DS_Tong_12AS-AT-VH'!$A$9:$I$3045,MATCH(1,($A18='DS_Tong_12AS-AT-VH'!$A$9:$A$3045)*($P$4='DS_Tong_12AS-AT-VH'!$B$9:$B$3045),0),6),0)} -> Lê Nguyễn Hoàng | E18: {=IFERROR(INDEX('DS_Tong_12AS-AT-VH'!$A$9:$I$3045,MATCH(1,($A18='DS_Tong_12AS-AT-VH'!$A$9:$A$3045)*($P$4='DS_Tong_12AS-AT-VH'!$B$9:$B$3045),0),7),0)} -> Oanh | F18: {=IFERROR(INDEX('DS_Tong_12AS-AT-VH'!$A$9:$I$3045,MATCH(1,($A18='DS_Tong_12AS-AT-VH'!$A$9:$A$3045)*($P$4='DS_Tong_12AS-AT-VH'!$B$9:$B$3045),0),8),0)} -> 12AS11 | G18: {=IFERROR(INDEX('DS_Tong_12AS-AT-VH'!$A$9:$I$3045,MATCH(1,($A18='DS_Tong_12AS-AT-VH'!$A$9:$A$3045)*($P$4='DS_Tong_12AS-AT-VH'!$B$9:$B$3045),0),9),0)} -> 0 | P18: =IFERROR(VLOOKUP($C18,'DS_Tong_12AS-AT-VH'!$E$9:$S$3024,13,0),0) -> 0 | R18: 12 | S18: =S17+1 -> 47 | T18: =IFERROR(VLOOKUP($S18,TH_P.thi!$A$18:$P$165,3,0),0) -> 13A | U18: =IFERROR(VLOOKUP($S18,TH_P.thi!$A$18:$T$165,6,0),0) -> 13A.S2
A19: 11 | B19: {=IFERROR(INDEX('DS_Tong_12AS-AT-VH'!$A$9:$I$3045,MATCH(1,($A19='DS_Tong_12AS-AT-VH'!$A$9:$A$3045)*($P$4='DS_Tong_12AS-AT-VH'!$B$9:$B$3045),0),4),0)} -> P.7B | C19: {=IFERROR(INDEX('DS_Tong_12AS-AT-VH'!$A$9:$I$3045,MATCH(1,($A19='DS_Tong_12AS-AT-VH'!$A$9:$A$3045)*($P$4='DS_Tong_12AS-AT-VH'!$B$9:$B$3045),0),5),0)} -> 101428 | D19: {=IFERROR(INDEX('DS_Tong_12AS-AT-VH'!$A$9:$I$3045,MATCH(1,($A19='DS_Tong_12AS-AT-VH'!$A$9:$A$3045)*($P$4='DS_Tong_12AS-AT-VH'!$B$9:$B$3045),0),6),0)} -> Hà Nguyễn Đức | E19: {=IFERROR(INDEX('DS_Tong_12AS-AT-VH'!$A$9:$I$3045,MATCH(1,($A19='DS_Tong_12AS-AT-VH'!$A$9:$A$3045)*($P$4='DS_Tong_12AS-AT-VH'!$B$9:$B$3045),0),7),0)} -> Phát | F19: {=IFERROR(INDEX('DS_Tong_12AS-AT-VH'!$A$9:$I$3045,MATCH(1,($A19='DS_Tong_12AS-AT-VH'!$A$9:$A$3045)*($P$4='DS_Tong_12AS-AT-VH'!$B$9:$B$3045),0),8),0)} -> 12AS12 | G19: {=IFERROR(INDEX('DS_Tong_12AS-AT-VH'!$A$9:$I$3045,MATCH(1,($A19='DS_Tong_12AS-AT-VH'!$A$9:$A$3045)*($P$4='DS_Tong_12AS-AT-VH'!$B$9:$B$3045),0),9),0)} -> 0 | P19: =IFERROR(VLOOKUP($C19,'DS_Tong_12AS-AT-VH'!$E$9:$S$3024,13,0),0) -> 0 | R19: 13 | S19: =S18+1 -> 48 | T19: =IFERROR(VLOOKUP($S19,TH_P.thi!$A$18:$P$165,3,0),0) -> 14A | U19: =IFERROR(VLOOKUP($S19,TH_P.thi!$A$18:$T$165,6,0),0) -> 14A.S2
A20: 12 | B20: {=IFERROR(INDEX('DS_Tong_12AS-AT-VH'!$A$9:$I$3045,MATCH(1,($A20='DS_Tong_12AS-AT-VH'!$A$9:$A$3045)*($P$4='DS_Tong_12AS-AT-VH'!$B$9:$B$3045),0),4),0)} -> P.7B | C20: {=IFERROR(INDEX('DS_Tong_12AS-AT-VH'!$A$9:$I$3045,MATCH(1,($A20='DS_Tong_12AS-AT-VH'!$A$9:$A$3045)*($P$4='DS_Tong_12AS-AT-VH'!$B$9:$B$3045),0),5),0)} -> 101429 | D20: {=IFERROR(INDEX('DS_Tong_12AS-AT-VH'!$A$9:$I$3045,MATCH(1,($A20='DS_Tong_12AS-AT-VH'!$A$9:$A$3045)*($P$4='DS_Tong_12AS-AT-VH'!$B$9:$B$3045),0),6),0)} -> Lê Văn Tuấn | E20: {=IFERROR(INDEX('DS_Tong_12AS-AT-VH'!$A$9:$I$3045,MATCH(1,($A20='DS_Tong_12AS-AT-VH'!$A$9:$A$3045)*($P$4='DS_Tong_12AS-AT-VH'!$B$9:$B$3045),0),7),0)} -> Phát | F20: {=IFERROR(INDEX('DS_Tong_12AS-AT-VH'!$A$9:$I$3045,MATCH(1,($A20='DS_Tong_12AS-AT-VH'!$A$9:$A$3045)*($P$4='DS_Tong_12AS-AT-VH'!$B$9:$B$3045),0),8),0)} -> 12AS10 | G20: {=IFERROR(INDEX('DS_Tong_12AS-AT-VH'!$A$9:$I$3045,MATCH(1,($A20='DS_Tong_12AS-AT-VH'!$A$9:$A$3045)*($P$4='DS_Tong_12AS-AT-VH'!$B$9:$B$3045),0),9),0)} -> 0 | P20: =IFERROR(VLOOKUP($C20,'DS_Tong_12AS-AT-VH'!$E$9:$S$3024,13,0),0) -> 0 | R20: 14 | S20: =S19+1 -> 49 | T20: =IFERROR(VLOOKUP($S20,TH_P.thi!$A$18:$P$165,3,0),0) -> 2B | U20: =IFERROR(VLOOKUP($S20,TH_P.thi!$A$18:$T$165,6,0),0) -> 2B.S2
A21: 13 | B21: {=IFERROR(INDEX('DS_Tong_12AS-AT-VH'!$A$9:$I$3045,MATCH(1,($A21='DS_Tong_12AS-AT-VH'!$A$9:$A$3045)*($P$4='DS_Tong_12AS-AT-VH'!$B$9:$B$3045),0),4),0)} -> P.7B | C21: {=IFERROR(INDEX('DS_Tong_12AS-AT-VH'!$A$9:$I$3045,MATCH(1,($A21='DS_Tong_12AS-AT-VH'!$A$9:$A$3045)*($P$4='DS_Tong_12AS-AT-VH'!$B$9:$B$3045),0),5),0)} -> 101430 | D21: {=IFERROR(INDEX('DS_Tong_12AS-AT-VH'!$A$9:$I$3045,MATCH(1,($A21='DS_Tong_12AS-AT-VH'!$A$9:$A$3045)*($P$4='DS_Tong_12AS-AT-VH'!$B$9:$B$3045),0),6),0)} -> Trần Tuấn | E21: {=IFERROR(INDEX('DS_Tong_12AS-AT-VH'!$A$9:$I$3045,MATCH(1,($A21='DS_Tong_12AS-AT-VH'!$A$9:$A$3045)*($P$4='DS_Tong_12AS-AT-VH'!$B$9:$B$3045),0),7),0)} -> Phát | F21: {=IFERROR(INDEX('DS_Tong_12AS-AT-VH'!$A$9:$I$3045,MATCH(1,($A21='DS_Tong_12AS-AT-VH'!$A$9:$A$3045)*($P$4='DS_Tong_12AS-AT-VH'!$B$9:$B$3045),0),8),0)} -> 12AS10 | G21: {=IFERROR(INDEX('DS_Tong_12AS-AT-VH'!$A$9:$I$3045,MATCH(1,($A21='DS_Tong_12AS-AT-VH'!$A$9:$A$3045)*($P$4='DS_Tong_12AS-AT-VH'!$B$9:$B$3045),0),9),0)} -> 0 | P21: =IFERROR(VLOOKUP($C21,'DS_Tong_12AS-AT-VH'!$E$9:$S$3024,13,0),0) -> 0 | R21: 15 | S21: =S20+1 -> 50 | T21: =IFERROR(VLOOKUP($S21,TH_P.thi!$A$18:$P$165,3,0),0) -> 3B | U21: =IFERROR(VLOOKUP($S21,TH_P.thi!$A$18:$T$165,6,0),0) -> 3B.S2
... A27: 19 | B27: {=IFERROR(INDEX('DS_Tong_12AS-AT-VH'!$A$9:$I$3045,MATCH(1,($A27='DS_Tong_12AS-AT-VH'!$A$9:$A$3045)*($P$4='DS_Tong_12AS-AT-VH'!$B$9:$B$3045),0),4),0)} -> P.7B | C27: {=IFERROR(INDEX('DS_Tong_12AS-AT-VH'!$A$9:$I$3045,MATCH(1,($A27='DS_Tong_12AS-AT-VH'!$A$9:$A$3045)*($P$4='DS_Tong_12AS-AT-VH'!$B$9:$B$3045),0),5),0)} -> 101436 | D27: {=IFERROR(INDEX('DS_Tong_12AS-AT-VH'!$A$9:$I$3045,MATCH(1,($A27='DS_Tong_12AS-AT-VH'!$A$9:$A$3045)*($P$4='DS_Tong_12AS-AT-VH'!$B$9:$B$3045),0),6),0)} -> Lê Thảo | E27: {=IFERROR(INDEX('DS_Tong_12AS-AT-VH'!$A$9:$I$3045,MATCH(1,($A27='DS_Tong_12AS-AT-VH'!$A$9:$A$3045)*($P$4='DS_Tong_12AS-AT-VH'!$B$9:$B$3045),0),7),0)} -> Phương | F27: {=IFERROR(INDEX('DS_Tong_12AS-AT-VH'!$A$9:$I$3045,MATCH(1,($A27='DS_Tong_12AS-AT-VH'!$A$9:$A$3045)*($P$4='DS_Tong_12AS-AT-VH'!$B$9:$B$3045),0),8),0)} -> 12AS10 | G27: {=IFERROR(INDEX('DS_Tong_12AS-AT-VH'!$A$9:$I$3045,MATCH(1,($A27='DS_Tong_12AS-AT-VH'!$A$9:$A$3045)*($P$4='DS_Tong_12AS-AT-VH'!$B$9:$B$3045),0),9),0)} -> 0 | P27: =IFERROR(VLOOKUP($C27,'DS_Tong_12AS-AT-VH'!$E$9:$S$3024,13,0),0) -> 0 | R27: 21 | S27: =S26+1 -> 56 | T27: =IFERROR(VLOOKUP($S27,TH_P.thi!$A$18:$P$165,3,0),0) -> 9B | U27: =IFERROR(VLOOKUP($S27,TH_P.thi!$A$18:$T$165,6,0),0) -> 9B.S2
A28: 20 | B28: {=IFERROR(INDEX('DS_Tong_12AS-AT-VH'!$A$9:$I$3045,MATCH(1,($A28='DS_Tong_12AS-AT-VH'!$A$9:$A$3045)*($P$4='DS_Tong_12AS-AT-VH'!$B$9:$B$3045),0),4),0)} -> P.7B | C28: {=IFERROR(INDEX('DS_Tong_12AS-AT-VH'!$A$9:$I$3045,MATCH(1,($A28='DS_Tong_12AS-AT-VH'!$A$9:$A$3045)*($P$4='DS_Tong_12AS-AT-VH'!$B$9:$B$3045),0),5),0)} -> 101437 | D28: {=IFERROR(INDEX('DS_Tong_12AS-AT-VH'!$A$9:$I$3045,MATCH(1,($A28='DS_Tong_12AS-AT-VH'!$A$9:$A$3045)*($P$4='DS_Tong_12AS-AT-VH'!$B$9:$B$3045),0),6),0)} -> Nguyễn Thị Trúc | E28: {=IFERROR(INDEX('DS_Tong_12AS-AT-VH'!$A$9:$I$3045,MATCH(1,($A28='DS_Tong_12AS-AT-VH'!$A$9:$A$3045)*($P$4='DS_Tong_12AS-AT-VH'!$B$9:$B$3045),0),7),0)} -> Phương | F28: {=IFERROR(INDEX('DS_Tong_12AS-AT-VH'!$A$9:$I$3045,MATCH(1,($A28='DS_Tong_12AS-AT-VH'!$A$9:$A$3045)*($P$4='DS_Tong_12AS-AT-VH'!$B$9:$B$3045),0),8),0)} -> 12AS9 | G28: {=IFERROR(INDEX('DS_Tong_12AS-AT-VH'!$A$9:$I$3045,MATCH(1,($A28='DS_Tong_12AS-AT-VH'!$A$9:$A$3045)*($P$4='DS_Tong_12AS-AT-VH'!$B$9:$B$3045),0),9),0)} -> 0 | P28: =IFERROR(VLOOKUP($C28,'DS_Tong_12AS-AT-VH'!$E$9:$S$3024,13,0),0) -> 0 | R28: 22 | T28: =IFERROR(VLOOKUP($S28,TH_P.thi!$A$18:$P$165,3,0),0) -> 0 | U28: =IFERROR(VLOOKUP($S28,TH_P.thi!$A$18:$T$165,6,0),0) -> 0
A29: 21 | B29: {=IFERROR(INDEX('DS_Tong_12AS-AT-VH'!$A$9:$I$3045,MATCH(1,($A29='DS_Tong_12AS-AT-VH'!$A$9:$A$3045)*($P$4='DS_Tong_12AS-AT-VH'!$B$9:$B$3045),0),4),0)} -> P.7B | C29: {=IFERROR(INDEX('DS_Tong_12AS-AT-VH'!$A$9:$I$3045,MATCH(1,($A29='DS_Tong_12AS-AT-VH'!$A$9:$A$3045)*($P$4='DS_Tong_12AS-AT-VH'!$B$9:$B$3045),0),5),0)} -> 101438 | D29: {=IFERROR(INDEX('DS_Tong_12AS-AT-VH'!$A$9:$I$3045,MATCH(1,($A29='DS_Tong_12AS-AT-VH'!$A$9:$A$3045)*($P$4='DS_Tong_12AS-AT-VH'!$B$9:$B$3045),0),6),0)} -> Phan Thị Kim | E29: {=IFERROR(INDEX('DS_Tong_12AS-AT-VH'!$A$9:$I$3045,MATCH(1,($A29='DS_Tong_12AS-AT-VH'!$A$9:$A$3045)*($P$4='DS_Tong_12AS-AT-VH'!$B$9:$B$3045),0),7),0)} -> Phương | F29: {=IFERROR(INDEX('DS_Tong_12AS-AT-VH'!$A$9:$I$3045,MATCH(1,($A29='DS_Tong_12AS-AT-VH'!$A$9:$A$3045)*($P$4='DS_Tong_12AS-AT-VH'!$B$9:$B$3045),0),8),0)} -> 12AS11 | G29: {=IFERROR(INDEX('DS_Tong_12AS-AT-VH'!$A$9:$I$3045,MATCH(1,($A29='DS_Tong_12AS-AT-VH'!$A$9:$A$3045)*($P$4='DS_Tong_12AS-AT-VH'!$B$9:$B$3045),0),9),0)} -> 0 | P29: =IFERROR(VLOOKUP($C29,'DS_Tong_12AS-AT-VH'!$E$9:$S$3024,13,0),0) -> 0 | R29: 23 | T29: =IFERROR(VLOOKUP($S29,TH_P.thi!$A$18:$P$165,3,0),0) -> 0 | U29: =IFERROR(VLOOKUP($S29,TH_P.thi!$A$18:$T$165,6,0),0) -> 0
A30: 22 | B30: {=IFERROR(INDEX('DS_Tong_12AS-AT-VH'!$A$9:$I$3045,MATCH(1,($A30='DS_Tong_12AS-AT-VH'!$A$9:$A$3045)*($P$4='DS_Tong_12AS-AT-VH'!$B$9:$B$3045),0),4),0)} -> P.7B | C30: {=IFERROR(INDEX('DS_Tong_12AS-AT-VH'!$A$9:$I$3045,MATCH(1,($A30='DS_Tong_12AS-AT-VH'!$A$9:$A$3045)*($P$4='DS_Tong_12AS-AT-VH'!$B$9:$B$3045),0),5),0)} -> 101439 | D30: {=IFERROR(INDEX('DS_Tong_12AS-AT-VH'!$A$9:$I$3045,MATCH(1,($A30='DS_Tong_12AS-AT-VH'!$A$9:$A$3045)*($P$4='DS_Tong_12AS-AT-VH'!$B$9:$B$3045),0),6),0)} -> Vũ Hoàng Minh | E30: {=IFERROR(INDEX('DS_Tong_12AS-AT-VH'!$A$9:$I$3045,MATCH(1,($A30='DS_Tong_12AS-AT-VH'!$A$9:$A$3045)*($P$4='DS_Tong_12AS-AT-VH'!$B$9:$B$3045),0),7),0)} -> Phương | F30: {=IFERROR(INDEX('DS_Tong_12AS-AT-VH'!$A$9:$I$3045,MATCH(1,($A30='DS_Tong_12AS-AT-VH'!$A$9:$A$3045)*($P$4='DS_Tong_12AS-AT-VH'!$B$9:$B$3045),0),8),0)} -> 12AS11 | G30: {=IFERROR(INDEX('DS_Tong_12AS-AT-VH'!$A$9:$I$3045,MATCH(1,($A30='DS_Tong_12AS-AT-VH'!$A$9:$A$3045)*($P$4='DS_Tong_12AS-AT-VH'!$B$9:$B$3045),0),9),0)} -> 0 | P30: =IFERROR(VLOOKUP($C30,'DS_Tong_12AS-AT-VH'!$E$9:$S$3024,13,0),0) -> 0 | R30: 24 | T30: =IFERROR(VLOOKUP($S30,TH_P.thi!$A$18:$P$165,3,0),0) -> 0 | U30: =IFERROR(VLOOKUP($S30,TH_P.thi!$A$18:$T$165,6,0),0) -> 0
A31: 23 | B31: {=IFERROR(INDEX('DS_Tong_12AS-AT-VH'!$A$9:$I$3045,MATCH(1,($A31='DS_Tong_12AS-AT-VH'!$A$9:$A$3045)*($P$4='DS_Tong_12AS-AT-VH'!$B$9:$B$3045),0),4),0)} -> P.7B | C31: {=IFERROR(INDEX('DS_Tong_12AS-AT-VH'!$A$9:$I$3045,MATCH(1,($A31='DS_Tong_12AS-AT-VH'!$A$9:$A$3045)*($P$4='DS_Tong_12AS-AT-VH'!$B$9:$B$3045),0),5),0)} -> 101440 | D31: {=IFERROR(INDEX('DS_Tong_12AS-AT-VH'!$A$9:$I$3045,MATCH(1,($A31='DS_Tong_12AS-AT-VH'!$A$9:$A$3045)*($P$4='DS_Tong_12AS-AT-VH'!$B$9:$B$3045),0),6),0)} -> Châu Ngọc | E31: {=IFERROR(INDEX('DS_Tong_12AS-AT-VH'!$A$9:$I$3045,MATCH(1,($A31='DS_Tong_12AS-AT-VH'!$A$9:$A$3045)*($P$4='DS_Tong_12AS-AT-VH'!$B$9:$B$3045),0),7),0)} -> Quý | F31: {=IFERROR(INDEX('DS_Tong_12AS-AT-VH'!$A$9:$I$3045,MATCH(1,($A31='DS_Tong_12AS-AT-VH'!$A$9:$A$3045)*($P$4='DS_Tong_12AS-AT-VH'!$B$9:$B$3045),0),8),0)} -> 12AS10 | G31: {=IFERROR(INDEX('DS_Tong_12AS-AT-VH'!$A$9:$I$3045,MATCH(1,($A31='DS_Tong_12AS-AT-VH'!$A$9:$A$3045)*($P$4='DS_Tong_12AS-AT-VH'!$B$9:$B$3045),0),9),0)} -> 0 | P31: =IFERROR(VLOOKUP($C31,'DS_Tong_12AS-AT-VH'!$E$9:$S$3024,13,0),0) -> 0 | R31: 25 | T31: =IFERROR(VLOOKUP($S31,TH_P.thi!$A$18:$P$165,3,0),0) -> 0 | U31: =IFERROR(VLOOKUP($S31,TH_P.thi!$A$18:$T$165,6,0),0) -> 0
A32: 24 | B32: {=IFERROR(INDEX('DS_Tong_12AS-AT-VH'!$A$9:$I$3045,MATCH(1,($A32='DS_Tong_12AS-AT-VH'!$A$9:$A$3045)*($P$4='DS_Tong_12AS-AT-VH'!$B$9:$B$3045),0),4),0)} -> P.7B | C32: {=IFERROR(INDEX('DS_Tong_12AS-AT-VH'!$A$9:$I$3045,MATCH(1,($A32='DS_Tong_12AS-AT-VH'!$A$9:$A$3045)*($P$4='DS_Tong_12AS-AT-VH'!$B$9:$B$3045),0),5),0)} -> 101441 | D32: {=IFERROR(INDEX('DS_Tong_12AS-AT-VH'!$A$9:$I$3045,MATCH(1,($A32='DS_Tong_12AS-AT-VH'!$A$9:$A$3045)*($P$4='DS_Tong_12AS-AT-VH'!$B$9:$B$3045),0),6),0)} -> Nguyễn Mai Gia Phú | E32: {=IFERROR(INDEX('DS_Tong_12AS-AT-VH'!$A$9:$I$3045,MATCH(1,($A32='DS_Tong_12AS-AT-VH'!$A$9:$A$3045)*($P$4='DS_Tong_12AS-AT-VH'!$B$9:$B$3045),0),7),0)} -> Quý | F32: {=IFERROR(INDEX('DS_Tong_12AS-AT-VH'!$A$9:$I$3045,MATCH(1,($A32='DS_Tong_12AS-AT-VH'!$A$9:$A$3045)*($P$4='DS_Tong_12AS-AT-VH'!$B$9:$B$3045),0),8),0)} -> 12AS12 | G32: {=IFERROR(INDEX('DS_Tong_12AS-AT-VH'!$A$9:$I$3045,MATCH(1,($A32='DS_Tong_12AS-AT-VH'!$A$9:$A$3045)*($P$4='DS_Tong_12AS-AT-VH'!$B$9:$B$3045),0),9),0)} -> 0 | P32: =IFERROR(VLOOKUP($C32,'DS_Tong_12AS-AT-VH'!$E$9:$S$3024,13,0),0) -> 0 | R32: 26 | T32: =IFERROR(VLOOKUP($S32,TH_P.thi!$A$18:$P$165,3,0),0) -> 0 | U32: =IFERROR(VLOOKUP($S32,TH_P.thi!$A$18:$T$165,6,0),0) -> 0
A33: 25 | B33: {=IFERROR(INDEX('DS_Tong_12AS-AT-VH'!$A$9:$I$3045,MATCH(1,($A33='DS_Tong_12AS-AT-VH'!$A$9:$A$3045)*($P$4='DS_Tong_12AS-AT-VH'!$B$9:$B$3045),0),4),0)} -> P.7B | C33: {=IFERROR(INDEX('DS_Tong_12AS-AT-VH'!$A$9:$I$3045,MATCH(1,($A33='DS_Tong_12AS-AT-VH'!$A$9:$A$3045)*($P$4='DS_Tong_12AS-AT-VH'!$B$9:$B$3045),0),5),0)} -> 101442 | D33: {=IFERROR(INDEX('DS_Tong_12AS-AT-VH'!$A$9:$I$3045,MATCH(1,($A33='DS_Tong_12AS-AT-VH'!$A$9:$A$3045)*($P$4='DS_Tong_12AS-AT-VH'!$B$9:$B$3045),0),6),0)} -> Nguyễn Như | E33: {=IFERROR(INDEX('DS_Tong_12AS-AT-VH'!$A$9:$I$3045,MATCH(1,($A33='DS_Tong_12AS-AT-VH'!$A$9:$A$3045)*($P$4='DS_Tong_12AS-AT-VH'!$B$9:$B$3045),0),7),0)} -> Quỳnh | F33: {=IFERROR(INDEX('DS_Tong_12AS-AT-VH'!$A$9:$I$3045,MATCH(1,($A33='DS_Tong_12AS-AT-VH'!$A$9:$A$3045)*($P$4='DS_Tong_12AS-AT-VH'!$B$9:$B$3045),0),8),0)} -> 12AS11 | G33: {=IFERROR(INDEX('DS_Tong_12AS-AT-VH'!$A$9:$I$3045,MATCH(1,($A33='DS_Tong_12AS-AT-VH'!$A$9:$A$3045)*($P$4='DS_Tong_12AS-AT-VH'!$B$9:$B$3045),0),9),0)} -> 0 | P33: =IFERROR(VLOOKUP($C33,'DS_Tong_12AS-AT-VH'!$E$9:$S$3024,13,0),0) -> 0 | R33: 27 | T33: =IFERROR(VLOOKUP($S33,TH_P.thi!$A$18:$P$165,3,0),0) -> 0 | U33: =IFERROR(VLOOKUP($S33,TH_P.thi!$A$18:$T$165,6,0),0) -> 0
A34: 26 | B34: {=IFERROR(INDEX('DS_Tong_12AS-AT-VH'!$A$9:$I$3045,MATCH(1,($A34='DS_Tong_12AS-AT-VH'!$A$9:$A$3045)*($P$4='DS_Tong_12AS-AT-VH'!$B$9:$B$3045),0),4),0)} -> P.7B | C34: {=IFERROR(INDEX('DS_Tong_12AS-AT-VH'!$A$9:$I$3045,MATCH(1,($A34='DS_Tong_12AS-AT-VH'!$A$9:$A$3045)*($P$4='DS_Tong_12AS-AT-VH'!$B$9:$B$3045),0),5),0)} -> 101443 | D34: {=IFERROR(INDEX('DS_Tong_12AS-AT-VH'!$A$9:$I$3045,MATCH(1,($A34='DS_Tong_12AS-AT-VH'!$A$9:$A$3045)*($P$4='DS_Tong_12AS-AT-VH'!$B$9:$B$3045),0),6),0)} -> Nguyễn Huỳnh Kim | E34: {=IFERROR(INDEX('DS_Tong_12AS-AT-VH'!$A$9:$I$3045,MATCH(1,($A34='DS_Tong_12AS-AT-VH'!$A$9:$A$3045)*($P$4='DS_Tong_12AS-AT-VH'!$B$9:$B$3045),0),7),0)} -> Ngân | F34: {=IFERROR(INDEX('DS_Tong_12AS-AT-VH'!$A$9:$I$3045,MATCH(1,($A34='DS_Tong_12AS-AT-VH'!$A$9:$A$3045)*($P$4='DS_Tong_12AS-AT-VH'!$B$9:$B$3045),0),8),0)} -> 12AS9 | G34: {=IFERROR(INDEX('DS_Tong_12AS-AT-VH'!$A$9:$I$3045,MATCH(1,($A34='DS_Tong_12AS-AT-VH'!$A$9:$A$3045)*($P$4='DS_Tong_12AS-AT-VH'!$B$9:$B$3045),0),9),0)} -> HN | P34: =IFERROR(VLOOKUP($C34,'DS_Tong_12AS-AT-VH'!$E$9:$S$3024,13,0),0) -> 0 | R34: 28 | T34: =IFERROR(VLOOKUP($S34,TH_P.thi!$A$18:$P$165,3,0),0) -> 0 | U34: =IFERROR(VLOOKUP($S34,TH_P.thi!$A$18:$T$165,6,0),0) -> 0
A35: 27 | B35: {=IFERROR(INDEX('DS_Tong_12AS-AT-VH'!$A$9:$I$3045,MATCH(1,($A35='DS_Tong_12AS-AT-VH'!$A$9:$A$3045)*($P$4='DS_Tong_12AS-AT-VH'!$B$9:$B$3045),0),4),0)} -> P.7B | C35: {=IFERROR(INDEX('DS_Tong_12AS-AT-VH'!$A$9:$I$3045,MATCH(1,($A35='DS_Tong_12AS-AT-VH'!$A$9:$A$3045)*($P$4='DS_Tong_12AS-AT-VH'!$B$9:$B$3045),0),5),0)} -> 101444 | D35: {=IFERROR(INDEX('DS_Tong_12AS-AT-VH'!$A$9:$I$3045,MATCH(1,($A35='DS_Tong_12AS-AT-VH'!$A$9:$A$3045)*($P$4='DS_Tong_12AS-AT-VH'!$B$9:$B$3045),0),6),0)} -> Nguyễn Thị Yến | E35: {=IFERROR(INDEX('DS_Tong_12AS-AT-VH'!$A$9:$I$3045,MATCH(1,($A35='DS_Tong_12AS-AT-VH'!$A$9:$A$3045)*($P$4='DS_Tong_12AS-AT-VH'!$B$9:$B$3045),0),7),0)} -> Nhi | F35: {=IFERROR(INDEX('DS_Tong_12AS-AT-VH'!$A$9:$I$3045,MATCH(1,($A35='DS_Tong_12AS-AT-VH'!$A$9:$A$3045)*($P$4='DS_Tong_12AS-AT-VH'!$B$9:$B$3045),0),8),0)} -> 12AS11 | G35: {=IFERROR(INDEX('DS_Tong_12AS-AT-VH'!$A$9:$I$3045,MATCH(1,($A35='DS_Tong_12AS-AT-VH'!$A$9:$A$3045)*($P$4='DS_Tong_12AS-AT-VH'!$B$9:$B$3045),0),9),0)} -> HN | P35: =IFERROR(VLOOKUP($C35,'DS_Tong_12AS-AT-VH'!$E$9:$S$3024,13,0),0) -> 0 | R35: 29 | T35: =IFERROR(VLOOKUP($S35,TH_P.thi!$A$18:$P$165,3,0),0) -> 0 | U35: =IFERROR(VLOOKUP($S35,TH_P.thi!$A$18:$T$165,6,0),0) -> 0
A36: 28 | B36: {=IFERROR(INDEX('DS_Tong_12AS-AT-VH'!$A$9:$I$3045,MATCH(1,($A36='DS_Tong_12AS-AT-VH'!$A$9:$A$3045)*($P$4='DS_Tong_12AS-AT-VH'!$B$9:$B$3045),0),4),0)} -> 0 | C36: {=IFERROR(INDEX('DS_Tong_12AS-AT-VH'!$A$9:$I$3045,MATCH(1,($A36='DS_Tong_12AS-AT-VH'!$A$9:$A$3045)*($P$4='DS_Tong_12AS-AT-VH'!$B$9:$B$3045),0),5),0)} -> 0 | D36: {=IFERROR(INDEX('DS_Tong_12AS-AT-VH'!$A$9:$I$3045,MATCH(1,($A36='DS_Tong_12AS-AT-VH'!$A$9:$A$3045)*($P$4='DS_Tong_12AS-AT-VH'!$B$9:$B$3045),0),6),0)} -> 0 | E36: {=IFERROR(INDEX('DS_Tong_12AS-AT-VH'!$A$9:$I$3045,MATCH(1,($A36='DS_Tong_12AS-AT-VH'!$A$9:$A$3045)*($P$4='DS_Tong_12AS-AT-VH'!$B$9:$B$3045),0),7),0)} -> 0 | F36: {=IFERROR(INDEX('DS_Tong_12AS-AT-VH'!$A$9:$I$3045,MATCH(1,($A36='DS_Tong_12AS-AT-VH'!$A$9:$A$3045)*($P$4='DS_Tong_12AS-AT-VH'!$B$9:$B$3045),0),8),0)} -> 0 | G36: {=IFERROR(INDEX('DS_Tong_12AS-AT-VH'!$A$9:$I$3045,MATCH(1,($A36='DS_Tong_12AS-AT-VH'!$A$9:$A$3045)*($P$4='DS_Tong_12AS-AT-VH'!$B$9:$B$3045),0),9),0)} -> 0 | P36: =IFERROR(VLOOKUP($C36,'DS_Tong_12AS-AT-VH'!$E$9:$S$3024,13,0),0) -> 0 | R36: 30 | T36: =IFERROR(VLOOKUP($S36,TH_P.thi!$A$18:$P$165,3,0),0) -> 0 | U36: =IFERROR(VLOOKUP($S36,TH_P.thi!$A$18:$T$165,6,0),0) -> 0
A37: 29 | B37: {=IFERROR(INDEX('DS_Tong_12AS-AT-VH'!$A$9:$I$3045,MATCH(1,($A37='DS_Tong_12AS-AT-VH'!$A$9:$A$3045)*($P$4='DS_Tong_12AS-AT-VH'!$B$9:$B$3045),0),4),0)} -> 0 | C37: {=IFERROR(INDEX('DS_Tong_12AS-AT-VH'!$A$9:$I$3045,MATCH(1,($A37='DS_Tong_12AS-AT-VH'!$A$9:$A$3045)*($P$4='DS_Tong_12AS-AT-VH'!$B$9:$B$3045),0),5),0)} -> 0 | D37: {=IFERROR(INDEX('DS_Tong_12AS-AT-VH'!$A$9:$I$3045,MATCH(1,($A37='DS_Tong_12AS-AT-VH'!$A$9:$A$3045)*($P$4='DS_Tong_12AS-AT-VH'!$B$9:$B$3045),0),6),0)} -> 0 | E37: {=IFERROR(INDEX('DS_Tong_12AS-AT-VH'!$A$9:$I$3045,MATCH(1,($A37='DS_Tong_12AS-AT-VH'!$A$9:$A$3045)*($P$4='DS_Tong_12AS-AT-VH'!$B$9:$B$3045),0),7),0)} -> 0 | F37: {=IFERROR(INDEX('DS_Tong_12AS-AT-VH'!$A$9:$I$3045,MATCH(1,($A37='DS_Tong_12AS-AT-VH'!$A$9:$A$3045)*($P$4='DS_Tong_12AS-AT-VH'!$B$9:$B$3045),0),8),0)} -> 0 | G37: {=IFERROR(INDEX('DS_Tong_12AS-AT-VH'!$A$9:$I$3045,MATCH(1,($A37='DS_Tong_12AS-AT-VH'!$A$9:$A$3045)*($P$4='DS_Tong_12AS-AT-VH'!$B$9:$B$3045),0),9),0)} -> 0 | P37: =IFERROR(VLOOKUP($C37,'DS_Tong_12AS-AT-VH'!$E$9:$S$3024,13,0),0) -> 0 | R37: 31 | T37: =IFERROR(VLOOKUP($S37,TH_P.thi!$A$18:$P$165,3,0),0) -> 0 | U37: =IFERROR(VLOOKUP($S37,TH_P.thi!$A$18:$T$165,6,0),0) -> 0
A38: 30 | B38: {=IFERROR(INDEX('DS_Tong_12AS-AT-VH'!$A$9:$I$3045,MATCH(1,($A38='DS_Tong_12AS-AT-VH'!$A$9:$A$3045)*($P$4='DS_Tong_12AS-AT-VH'!$B$9:$B$3045),0),4),0)} -> 0 | C38: {=IFERROR(INDEX('DS_Tong_12AS-AT-VH'!$A$9:$I$3045,MATCH(1,($A38='DS_Tong_12AS-AT-VH'!$A$9:$A$3045)*($P$4='DS_Tong_12AS-AT-VH'!$B$9:$B$3045),0),5),0)} -> 0 | D38: {=IFERROR(INDEX('DS_Tong_12AS-AT-VH'!$A$9:$I$3045,MATCH(1,($A38='DS_Tong_12AS-AT-VH'!$A$9:$A$3045)*($P$4='DS_Tong_12AS-AT-VH'!$B$9:$B$3045),0),6),0)} -> 0 | E38: {=IFERROR(INDEX('DS_Tong_12AS-AT-VH'!$A$9:$I$3045,MATCH(1,($A38='DS_Tong_12AS-AT-VH'!$A$9:$A$3045)*($P$4='DS_Tong_12AS-AT-VH'!$B$9:$B$3045),0),7),0)} -> 0 | F38: {=IFERROR(INDEX('DS_Tong_12AS-AT-VH'!$A$9:$I$3045,MATCH(1,($A38='DS_Tong_12AS-AT-VH'!$A$9:$A$3045)*($P$4='DS_Tong_12AS-AT-VH'!$B$9:$B$3045),0),8),0)} -> 0 | G38: {=IFERROR(INDEX('DS_Tong_12AS-AT-VH'!$A$9:$I$3045,MATCH(1,($A38='DS_Tong_12AS-AT-VH'!$A$9:$A$3045)*($P$4='DS_Tong_12AS-AT-VH'!$B$9:$B$3045),0),9),0)} -> 0 | R38: 32 | T38: =IFERROR(VLOOKUP($S38,TH_P.thi!$A$18:$P$165,3,0),0) -> 0 | U38: =IFERROR(VLOOKUP($S38,TH_P.thi!$A$18:$T$165,6,0),0) -> 0
A39: 31 | B39: {=IFERROR(INDEX('DS_Tong_12AS-AT-VH'!$A$9:$I$3045,MATCH(1,($A39='DS_Tong_12AS-AT-VH'!$A$9:$A$3045)*($P$4='DS_Tong_12AS-AT-VH'!$B$9:$B$3045),0),4),0)} -> 0 | C39: {=IFERROR(INDEX('DS_Tong_12AS-AT-VH'!$A$9:$I$3045,MATCH(1,($A39='DS_Tong_12AS-AT-VH'!$A$9:$A$3045)*($P$4='DS_Tong_12AS-AT-VH'!$B$9:$B$3045),0),5),0)} -> 0 | D39: {=IFERROR(INDEX('DS_Tong_12AS-AT-VH'!$A$9:$I$3045,MATCH(1,($A39='DS_Tong_12AS-AT-VH'!$A$9:$A$3045)*($P$4='DS_Tong_12AS-AT-VH'!$B$9:$B$3045),0),6),0)} -> 0 | E39: {=IFERROR(INDEX('DS_Tong_12AS-AT-VH'!$A$9:$I$3045,MATCH(1,($A39='DS_Tong_12AS-AT-VH'!$A$9:$A$3045)*($P$4='DS_Tong_12AS-AT-VH'!$B$9:$B$3045),0),7),0)} -> 0 | F39: {=IFERROR(INDEX('DS_Tong_12AS-AT-VH'!$A$9:$I$3045,MATCH(1,($A39='DS_Tong_12AS-AT-VH'!$A$9:$A$3045)*($P$4='DS_Tong_12AS-AT-VH'!$B$9:$B$3045),0),8),0)} -> 0 | G39: {=IFERROR(INDEX('DS_Tong_12AS-AT-VH'!$A$9:$I$3045,MATCH(1,($A39='DS_Tong_12AS-AT-VH'!$A$9:$A$3045)*($P$4='DS_Tong_12AS-AT-VH'!$B$9:$B$3045),0),9),0)} -> 0 | R39: 33
A40: 32 | B40: {=IFERROR(INDEX('DS_Tong_12AS-AT-VH'!$A$9:$I$3045,MATCH(1,($A40='DS_Tong_12AS-AT-VH'!$A$9:$A$3045)*($P$4='DS_Tong_12AS-AT-VH'!$B$9:$B$3045),0),4),0)} -> 0 | C40: {=IFERROR(INDEX('DS_Tong_12AS-AT-VH'!$A$9:$I$3045,MATCH(1,($A40='DS_Tong_12AS-AT-VH'!$A$9:$A$3045)*($P$4='DS_Tong_12AS-AT-VH'!$B$9:$B$3045),0),5),0)} -> 0 | D40: {=IFERROR(INDEX('DS_Tong_12AS-AT-VH'!$A$9:$I$3045,MATCH(1,($A40='DS_Tong_12AS-AT-VH'!$A$9:$A$3045)*($P$4='DS_Tong_12AS-AT-VH'!$B$9:$B$3045),0),6),0)} -> 0 | E40: {=IFERROR(INDEX('DS_Tong_12AS-AT-VH'!$A$9:$I$3045,MATCH(1,($A40='DS_Tong_12AS-AT-VH'!$A$9:$A$3045)*($P$4='DS_Tong_12AS-AT-VH'!$B$9:$B$3045),0),7),0)} -> 0 | F40: {=IFERROR(INDEX('DS_Tong_12AS-AT-VH'!$A$9:$I$3045,MATCH(1,($A40='DS_Tong_12AS-AT-VH'!$A$9:$A$3045)*($P$4='DS_Tong_12AS-AT-VH'!$B$9:$B$3045),0),8),0)} -> 0 | G40: {=IFERROR(INDEX('DS_Tong_12AS-AT-VH'!$A$9:$I$3045,MATCH(1,($A40='DS_Tong_12AS-AT-VH'!$A$9:$A$3045)*($P$4='DS_Tong_12AS-AT-VH'!$B$9:$B$3045),0),9),0)} -> 0 | P40: =IFERROR(VLOOKUP($C40,'DS_Tong_12AS-AT-VH'!$E$9:$S$3024,13,0),0) -> 0 | R40: 34 | T40: =IFERROR(VLOOKUP($S40,TH_P.thi!$A$18:$P$165,3,0),0) -> 0 | U40: =IFERROR(VLOOKUP($S40,TH_P.thi!$A$18:$T$165,6,0),0) -> 0
A41: Tổng cộng số bài thi: | P41: =IFERROR(VLOOKUP($C41,'DS_Tong_12AS-AT-VH'!$E$9:$S$3024,13,0),0) -> 0
A42: Giám thị: | H42: Ký tên:…………………………….. | J42: Ký tên:…………………………….. | L42: Ký tên:…………………………….. | N42: Ký tên:……………………………..

Sheet Nghi hoc T12
A1: SỞ GIÁO DỤC VÀ ĐÀO TẠO THÀNH PHỐ HỒ CHÍ MINH | B1: SỞ GIÁO DỤC VÀ ĐÀO TẠO THÀNH PHỐ HỒ CHÍ MINH | C1: SỞ GIÁO DỤC VÀ ĐÀO TẠO THÀNH PHỐ HỒ CHÍ MINH | D1: SỞ GIÁO DỤC VÀ ĐÀO TẠO THÀNH PHỐ HỒ CHÍ MINH
A2: TT GDNN-GDTX THÀNH PHỐ THỦ ĐỨC | B2: TT GDNN-GDTX THÀNH PHỐ THỦ ĐỨC | C2: TT GDNN-GDTX THÀNH PHỐ THỦ ĐỨC | D2: TT GDNN-GDTX THÀNH PHỐ THỦ ĐỨC
A3: DANH SÁCH THÔNG TIN HỒ SƠ - KẾT QUẢ HỌC TẬP HỌC SINH | B3: DANH SÁCH THÔNG TIN HỒ SƠ - KẾT QUẢ HỌC TẬP HỌC SINH | C3: DANH SÁCH THÔNG TIN HỒ SƠ - KẾT QUẢ HỌC TẬP HỌC SINH | D3: DANH SÁCH THÔNG TIN HỒ SƠ - KẾT QUẢ HỌC TẬP HỌC SINH | E3: DANH SÁCH THÔNG TIN HỒ SƠ - KẾT QUẢ HỌC TẬP HỌC SINH | F3: DANH SÁCH THÔNG TIN HỒ SƠ - KẾT QUẢ HỌC TẬP HỌC SINH | G3: DANH SÁCH THÔNG TIN HỒ SƠ - KẾT QUẢ HỌC TẬP HỌC SINH
A4: Năm học: 2025-2026 | B4: Năm học: 2025-2026 | C4: Năm học: 2025-2026 | D4: Năm học: 2025-2026 | E4: Năm học: 2025-2026 | F4: Năm học: 2025-2026 | G4: Năm học: 2025-2026
A6: STT | B6: Lớp học | C6: Họ tên | D6: Ngày sinh | E6: Giới tính | F6: Dân tộc | G6: Trạng thái
A7: 1 | B7: 10AS1 | C7: Huỳnh Thị Ngọc Anh | D7: 07/09/2010 | E7: Nữ | F7: Kinh | G7: Thôi học kỳ 1 | H7: =C7&"_"&B7 -> Huỳnh Thị Ngọc Anh_10AS1 | I7: NgiH
A8: 2 | B8: 10AS1 | C8: Nguyễn Quý Ngọc Thiện | D8: 16/09/2007 | E8: Nam | F8: Kinh | G8: Thôi học kỳ 1 | H8: =C8&"_"&B8 -> Nguyễn Quý Ngọc Thiện_10AS1 | I8: NgiH
A9: 3 | B9: 10AS4 | C9: Trương Tiến Dũng | D9: 24/06/2010 | E9: Nam | F9: Kinh | G9: Thôi học kỳ 1 | H9: =C9&"_"&B9 -> Trương Tiến Dũng_10AS4 | I9: NgiH
A10: 4 | B10: 10AS5 | C10: Đỗ Thiên Hồng Anh | D10: 30/08/2008 | E10: Nam | F10: Kinh | G10: Thôi học kỳ 1 | H10: =C10&"_"&B10 -> Đỗ Thiên Hồng Anh_10AS5 | I10: NgiH
A11: 5 | B11: 10AS5 | C11: Phạm Hoàng Bảo Quý | D11: 23/01/2010 | E11: Nam | F11: Mường | G11: Thôi học kỳ 1 | H11: =C11&"_"&B11 -> Phạm Hoàng Bảo Quý_10AS5 | I11: NgiH
A12: 6 | B12: 10AS6 | C12: Phan Văn Vũ Khang | D12: 05/10/2010 | E12: Nam | F12: Kinh | G12: Thôi học kỳ 1 | H12: =C12&"_"&B12 -> Phan Văn Vũ Khang_10AS6 | I12: NgiH
A13: 7 | B13: 10AS7 | C13: Lê Thanh Lâm | D13: 25/05/2009 | E13: Nam | F13: Kinh | G13: Thôi học kỳ 1 | H13: =C13&"_"&B13 -> Lê Thanh Lâm_10AS7 | I13: NgiH
A14: 8 | B14: 10AT1 | C14: Lê Châu Tuấn Đạt | D14: 18/08/1999 | E14: Nam | F14: Kinh | G14: Thôi học kỳ 1 | H14: =C14&"_"&B14 -> Lê Châu Tuấn Đạt_10AT1 | I14: NgiH
A15: 9 | B15: 10AT1 | C15: Lê Quốc Huy | D15: 01/09/2009 | E15: Nam | F15: Kinh | G15: Thôi học kỳ 1 | H15: =C15&"_"&B15 -> Lê Quốc Huy_10AT1 | I15: NgiH
A16: 10 | B16: 10AT1 | C16: Lê Lợi | D16: 09/07/2000 | E16: Nam | F16: Kinh | G16: Thôi học kỳ 1 | H16: =C16&"_"&B16 -> Lê Lợi_10AT1 | I16: NgiH
A17: 11 | B17: 10AT1 | C17: Đỗ Minh Phụng | D17: 23/10/1996 | E17: Nam | F17: Kinh | G17: Thôi học kỳ 1 | H17: =C17&"_"&B17 -> Đỗ Minh Phụng_10AT1 | I17: NgiH
A18: 12 | B18: 10AT2 | C18: Đinh Tuấn Anh | D18: 02/06/2008 | E18: Nam | F18: Kinh | G18: Thôi học kỳ 1 | H18: =C18&"_"&B18 -> Đinh Tuấn Anh_10AT2 | I18: NgiH
... A160: 154 | B160: 12KT4 | C160: Đoàn Nguyễn Đức Sơn | D160: 05/11/2008 | E160: Nam | F160: Kinh | G160: Thôi học kỳ 1 | H160: =C160&"_"&B160 -> Đoàn Nguyễn Đức Sơn_12KT4 | I160: NgiH
D163: Người lập biểu (Ký và ghi rõ họ tên)

Sheet No_HP
B1: Tên HV_KT gửi DS | C1: =COUNTIF(C2:C514,"HP") -> 506 | D1: =COUNTIF(D2:D514,"HP") -> 0 | E1: =C1-D1 -> 506
A2: 1 | B2: Lê Tuấn Anh_12AS1 | C2: HP | D2: =VLOOKUP(B2,'DS_Tong_12AS-AT-VH'!$T$9:$V$3025,3,0) -> #N/A
A3: 2 | B3: Nguyễn Thị Vân Anh_12AS1 | C3: HP | D3: =VLOOKUP(B3,'DS_Tong_12AS-AT-VH'!$T$9:$V$3025,3,0) -> #N/A
A4: 3 | B4: Phạm Vàng Anh_12AS1 | C4: HP | D4: =VLOOKUP(B4,'DS_Tong_12AS-AT-VH'!$T$9:$V$3025,3,0) -> #N/A
A5: 4 | B5: Nguyễn Khắc Thái Bảo_12AS1 | C5: HP | D5: =VLOOKUP(B5,'DS_Tong_12AS-AT-VH'!$T$9:$V$3025,3,0) -> #N/A
A6: 5 | B6: Nguyễn Thị Mỹ Duyên_12AS1 | C6: HP | D6: =VLOOKUP(B6,'DS_Tong_12AS-AT-VH'!$T$9:$V$3025,3,0) -> #N/A
A7: 6 | B7: Đặng Hoàng Trung Hiếu_12AS1 | C7: HP | D7: =VLOOKUP(B7,'DS_Tong_12AS-AT-VH'!$T$9:$V$3025,3,0) -> #N/A
A8: 7 | B8: Thái Xuân Hiếu_12AS1 | C8: HP | D8: =VLOOKUP(B8,'DS_Tong_12AS-AT-VH'!$T$9:$V$3025,3,0) -> #N/A
A9: 8 | B9: Nguyễn Ngọc Trường Huy_12AS1 | C9: HP | D9: =VLOOKUP(B9,'DS_Tong_12AS-AT-VH'!$T$9:$V$3025,3,0) -> #N/A
A10: 9 | B10: Thái Bá Huy_12AS1 | C10: HP | D10: =VLOOKUP(B10,'DS_Tong_12AS-AT-VH'!$T$9:$V$3025,3,0) -> #N/A
A11: 10 | B11: Phạm Tuấn Khải_12AS1 | C11: HP | D11: =VLOOKUP(B11,'DS_Tong_12AS-AT-VH'!$T$9:$V$3025,3,0) -> #N/A
A12: 11 | B12: Nguyễn Dương Hoàng Khang_12AS1 | C12: HP | D12: =VLOOKUP(B12,'DS_Tong_12AS-AT-VH'!$T$9:$V$3025,3,0) -> #N/A
A13: 12 | B13: Phan Nguyễn Phúc Khang_12AS1 | C13: HP | D13: =VLOOKUP(B13,'DS_Tong_12AS-AT-VH'!$T$9:$V$3025,3,0) -> #N/A
... A17: 16 | B17: Hoàng Long Nhật_12AS1 | C17: HP | D17: =VLOOKUP(B17,'DS_Tong_12AS-AT-VH'!$T$9:$V$3025,3,0) -> #N/A
A18: 17 | B18: Nguyễn Ngọc Quỳnh Như_12AS1 | C18: HP | D18: =VLOOKUP(B18,'DS_Tong_12AS-AT-VH'!$T$9:$V$3025,3,0) -> #N/A | E18: Nghỉ học
A19: 18 | B19: Kiều Minh Nhựt_12AS1 | C19: HP | D19: =VLOOKUP(B19,'DS_Tong_12AS-AT-VH'!$T$9:$V$3025,3,0) -> #N/A
A20: 19 | B20: Võ Minh Duy Phúc_12AS1 | C20: HP | D20: =VLOOKUP(B20,'DS_Tong_12AS-AT-VH'!$T$9:$V$3025,3,0) -> #N/A
A21: 20 | B21: Đặng Minh Quân_12AS1 | C21: HP | D21: =VLOOKUP(B21,'DS_Tong_12AS-AT-VH'!$T$9:$V$3025,3,0) -> #N/A
A22: 21 | B22: Lâm Chí Tài_12AS1 | C22: HP | D22: =VLOOKUP(B22,'DS_Tong_12AS-AT-VH'!$T$9:$V$3025,3,0) -> #N/A
A23: 22 | B23: Phan Ngọc Thuỷ Tiên_12AS1 | C23: HP | D23: =VLOOKUP(B23,'DS_Tong_12AS-AT-VH'!$T$9:$V$3025,3,0) -> #N/A
A24: 23 | B24: Nguyễn Thị Thanh Tuyền_12AS1 | C24: HP | D24: =VLOOKUP(B24,'DS_Tong_12AS-AT-VH'!$T$9:$V$3025,3,0) -> #N/A
A25: 24 | B25: Oghaekor Jacob Ohiorenua Thành_12AS1 | C25: HP | D25: =VLOOKUP(B25,'DS_Tong_12AS-AT-VH'!$T$9:$V$3025,3,0) -> #N/A
A26: 25 | B26: Nguyễn Ngọc Thảo_12AS1 | C26: HP | D26: =VLOOKUP(B26,'DS_Tong_12AS-AT-VH'!$T$9:$V$3025,3,0) -> #N/A
A27: 26 | B27: Nguyễn Cường Thịnh_12AS1 | C27: HP | D27: =VLOOKUP(B27,'DS_Tong_12AS-AT-VH'!$T$9:$V$3025,3,0) -> #N/A
A28: 27 | B28: Đoàn Nguyễn Minh Thông_12AS1 | C28: HP | D28: =VLOOKUP(B28,'DS_Tong_12AS-AT-VH'!$T$9:$V$3025,3,0) -> #N/A
A29: 28 | B29: Lê Thị Thùy Trang_12AS1 | C29: HP | D29: =VLOOKUP(B29,'DS_Tong_12AS-AT-VH'!$T$9:$V$3025,3,0) -> #N/A
A30: 29 | B30: Nguyễn Đoàn Thùy Trang_12AS1 | C30: HP | D30: =VLOOKUP(B30,'DS_Tong_12AS-AT-VH'!$T$9:$V$3025,3,0) -> #N/A
... A41: 40 | B41: Nguyễn Duy Hoàn_12AS10 | C41: HP | D41: =VLOOKUP(B41,'DS_Tong_12AS-AT-VH'!$T$9:$V$3025,3,0) -> #N/A
A42: 41 | B42: Phạm Việt Hùng_12AS10 | C42: HP | D42: =VLOOKUP(B42,'DS_Tong_12AS-AT-VH'!$T$9:$V$3025,3,0) -> #N/A | E42: Nghỉ học
A43: 42 | B43: Đặng Đình Tuấn Kiệt_12AS10 | C43: HP | D43: =VLOOKUP(B43,'DS_Tong_12AS-AT-VH'!$T$9:$V$3025,3,0) -> #N/A
A44: 43 | B44: Trần Minh Khang_12AS10 | C44: HP | D44: =VLOOKUP(B44,'DS_Tong_12AS-AT-VH'!$T$9:$V$3025,3,0) -> #N/A
A45: 44 | B45: Lý Ngọc Thùy Linh_12AS10 | C45: HP | D45: =VLOOKUP(B45,'DS_Tong_12AS-AT-VH'!$T$9:$V$3025,3,0) -> #N/A
A46: 45 | B46: Lâm Gia Luật_12AS10 | C46: HP | D46: =VLOOKUP(B46,'DS_Tong_12AS-AT-VH'!$T$9:$V$3025,3,0) -> #N/A
A47: 46 | B47: Lê Thị Kiều My_12AS10 | C47: HP | D47: =VLOOKUP(B47,'DS_Tong_12AS-AT-VH'!$T$9:$V$3025,3,0) -> #N/A
A48: 47 | B48: Nguyễn Thị Hà My_12AS10 | C48: HP | D48: =VLOOKUP(B48,'DS_Tong_12AS-AT-VH'!$T$9:$V$3025,3,0) -> #N/A
A49: 48 | B49: Nguyễn Ngọc Khánh Ngân_12AS10 | C49: HP | D49: =VLOOKUP(B49,'DS_Tong_12AS-AT-VH'!$T$9:$V$3025,3,0) -> #N/A
A50: 49 | B50: Trần Dương Bảo Ngọc_12AS10 | C50: HP | D50: =VLOOKUP(B50,'DS_Tong_12AS-AT-VH'!$T$9:$V$3025,3,0) -> #N/A
A51: 50 | B51: Phạm Minh Nhật_12AS10 | C51: HP | D51: =VLOOKUP(B51,'DS_Tong_12AS-AT-VH'!$T$9:$V$3025,3,0) -> #N/A
A52: 51 | B52: Nguyễn Thị Quỳnh Như_12AS10 | C52: HP | D52: =VLOOKUP(B52,'DS_Tong_12AS-AT-VH'!$T$9:$V$3025,3,0) -> #N/A
A53: 52 | B53: Nguyễn Thị Cẩm Tú_12AS10 | C53: HP | D53: =VLOOKUP(B53,'DS_Tong_12AS-AT-VH'!$T$9:$V$3025,3,0) -> #N/A
...

Sheet TH_P.thi
K1: 5 | L1: 6 | M1: 7 | N1: 8 | O1: 9 | P1: 10
B2: 25-26 | C2: ="LỚP "&D2&" -" -> LỚP 12AS - | D2: 12AS | E2: NGÀY THI: 22+24/12/2025 | H2: SÁNG | I2: Thứ Hai (22/12) | J2: Thứ Tư (24/12) | K2: Đ.chiếu DS trộn | L2: Chênh lệch
B3: 2025 - 2026 | C3: ="LỚP "&D3&" -" -> LỚP 12KT - | D3: 12KT | E3: NGÀY THI: 22+24/12/2025 | H3: SÁNG | I3: Thứ Hai (22/12) | J3: Thứ Tư (24/12) | M3: 2 | N3: 3 | O3: 4 | P3: 5
C4: ="LỚP "&D4&" -" -> LỚP 10VH - | D4: 10VH | E4: NGÀY THI: 22+24/12/2025 | H4: CHIỀU | I4: Thứ Hai (22/12) | J4: Thứ Tư (24/12)
C5: ="LỚP "&D5&" -" -> LỚP 10KT - | D5: 10KT | E5: NGÀY THI: 22+24/12/2025 | H5: CHIỀU | I5: Thứ Hai (22/12) | J5: Thứ Tư (24/12) | L5: TH1 | M5: VĂN | N5: LÝ | O5: TOÁN | P5: SỬ
C6: ="LỚP "&D6&" -" -> LỚP 12AT - | D6: 12AT | E6: NGÀY THI: 22+23/12/2025 | H6: TỐI | I6: Thứ Hai (22/12) | J6: Thứ Ba (23/12) | L6: TH2 | M6: VĂN | N6: HÓA | O6: TOÁN | P6: SỬ
C7: ="LỚP "&D7&" -" -> LỚP 12VH - | D7: 12VH | E7: NGÀY THI: 22+23/12/2025 | H7: TỐI | I7: Thứ Hai (22/12) | J7: Thứ Ba (23/12) | L7: TH3 | M7: VĂN | N7: KT-PL | O7: TOÁN | P7: SỬ
C8: ="LỚP "&D8&" -" -> LỚP 10AT - | D8: 10AT | E8: NGÀY THI: 22+23/12/2025 | H8: TỐI | I8: Thứ Hai (22/12) | J8: Thứ Ba (23/12) | L8: TH4 | M8: VĂN | N8: LÝ | O8: TOÁN | P8: SỬ
C9: ="LỚP "&D9&" -" -> LỚP 11AT - | D9: 11AT | E9: NGÀY THI: 22+23/12/2025 | H9: TỐI | I9: Thứ Hai (22/12) | J9: Thứ Ba (23/12) | L9: TH5 | M9: VĂN | N9: KT-PL | O9: TOÁN | P9: SỬ
C10: ="LỚP "&D10&" -" -> LỚP 10AS - | D10: 10AS | E10: NGÀY THI: 23+25/12/2025 | H10: SÁNG | I10: Thứ Ba (23/12) | J10: Thứ Năm (25/12) | L10: TH4 | M10: VĂN | N10: SINH | O10: TOÁN | P10: SỬ
C11: ="LỚP "&D11&" -" -> LỚP 11AS - | D11: 11AS | E11: NGÀY THI: 23+25/12/2025 | H11: SÁNG | I11: Thứ Ba (23/12) | J11: Thứ Năm (25/12)
C12: ="LỚP "&D12&" -" -> LỚP 11VH - | D12: 11VH | E12: NGÀY THI: 23+25/12/2025 | H12: CHIỀU | I12: Thứ Ba (23/12) | J12: Thứ Năm (25/12)
C13: ="LỚP "&D13&" -" -> LỚP 11KT - | D13: 11KT | E13: NGÀY THI: 23+25/12/2025 | H13: CHIỀU | I13: Thứ Ba (23/12) | J13: Thứ Năm (25/12)
A14: Cột 1 | B14: Cột 2 | C14: Cột 3 | D14: Cột 4 | E14: Cột 5 | F14: Cột 6 | G14: Cột 7 | H14: Cột 8 | I14: Cột 9 | J14: Cột 10 | K14: Cột 11 | L14: Cột 12 | M14: Cột 13 | N14: Cột 14 | O14: Cột 15 | P14: Cột 16 | Q14: Cột 17 | R14: Cột 18 | S14: Cột 19 | T14: Cột 20
A15: KH/Phòng | B15: COPPY T.KÊ P.THI | F15: TỰ LÀM | Q15: TỰ LÀM
B16: KHỐI 10AS | C16: 14 phòng | D16: 382
B17: TỔ HỢP 2 (10AS1,2) | D17: 93 | K17: =SUM(K18:K21) -> 93 | L17: =SUM(L18:L21) -> 0 | M17: =VLOOKUP($G18,$L$5:$P$10,M$3,0) -> VĂN | N17: =VLOOKUP($G18,$L$5:$P$10,N$3,0) -> HÓA | O17: =VLOOKUP($G18,$L$5:$P$10,O$3,0) -> TOÁN | P17: =VLOOKUP($G18,$L$5:$P$10,P$3,0) -> SỬ
A18: =IF(F18="","",SUBTOTAL(3,$F$18:F18)) -> 1 | B18: 1 | C18: 1A | D18: 24 | F18: =C18&".S" -> 1A.S | G18: TH2 | H18: 10AS | I18: =VLOOKUP($H18,$D$2:$J$13,6,0) -> Thứ Ba (23/12) | J18: =VLOOKUP($H18,$D$2:$J$13,7,0) -> Thứ Năm (25/12) | K18: =COUNTIF('DS_Tong_12AS-AT-VH'!$B$9:$B$426,F18) -> 24 | L18: =D18-K18 -> 0 | M18: =VLOOKUP($G18,$L$5:$P$9,M$3,0) -> VĂN | N18: =VLOOKUP($G18,$L$5:$P$9,N$3,0) -> HÓA | O18: =VLOOKUP($G18,$L$5:$P$9,O$3,0) -> TOÁN | P18: =VLOOKUP($G18,$L$5:$P$9,P$3,0) -> SỬ | Q18: 100001 | R18: =Q18+K18-1 -> 100024 | S18: TỔ HỢP 2 (10AS1,2) | T18: =VLOOKUP($H18,$D$2:$G$13,2,0) -> NGÀY THI: 23+25/12/2025
A19: =IF(F19="","",SUBTOTAL(3,$F$18:F19)) -> 2 | B19: 2 | C19: 2A | D19: 23 | F19: =C19&".S" -> 2A.S | G19: TH2 | H19: 10AS | I19: =VLOOKUP($H19,$D$2:$J$13,6,0) -> Thứ Ba (23/12) | J19: =VLOOKUP($H19,$D$2:$J$13,7,0) -> Thứ Năm (25/12) | K19: =COUNTIF('DS_Tong_12AS-AT-VH'!$B$9:$B$426,F19) -> 23 | L19: =D19-K19 -> 0 | M19: =VLOOKUP($G19,$L$5:$P$9,M$3,0) -> VĂN | N19: =VLOOKUP($G19,$L$5:$P$9,N$3,0) -> HÓA | O19: =VLOOKUP($G19,$L$5:$P$9,O$3,0) -> TOÁN | P19: =VLOOKUP($G19,$L$5:$P$9,P$3,0) -> SỬ | Q19: =Q18+K18 -> 100025 | R19: =Q19+K19-1 -> 100047 | S19: TỔ HỢP 2 (10AS1,2) | T19: =VLOOKUP($H19,$D$2:$G$13,2,0) -> NGÀY THI: 23+25/12/2025
A20: =IF(F20="","",SUBTOTAL(3,$F$18:F20)) -> 3 | B20: 3 | C20: 3A | D20: 23 | F20: =C20&".S" -> 3A.S | G20: TH2 | H20: 10AS | I20: =VLOOKUP($H20,$D$2:$J$13,6,0) -> Thứ Ba (23/12) | J20: =VLOOKUP($H20,$D$2:$J$13,7,0) -> Thứ Năm (25/12) | K20: =COUNTIF('DS_Tong_12AS-AT-VH'!$B$9:$B$426,F20) -> 23 | L20: =D20-K20 -> 0 | M20: =VLOOKUP($G20,$L$5:$P$9,M$3,0) -> VĂN | N20: =VLOOKUP($G20,$L$5:$P$9,N$3,0) -> HÓA | O20: =VLOOKUP($G20,$L$5:$P$9,O$3,0) -> TOÁN | P20: =VLOOKUP($G20,$L$5:$P$9,P$3,0) -> SỬ | Q20: =Q19+K19 -> 100048 | R20: =Q20+K20-1 -> 100070 | S20: TỔ HỢP 2 (10AS1,2) | T20: =VLOOKUP($H20,$D$2:$G$13,2,0) -> NGÀY THI: 23+25/12/2025
A21: =IF(F21="","",SUBTOTAL(3,$F$18:F21)) -> 4 | B21: 4 | C21: 4A | D21: 23 | F21: =C21&".S" -> 4A.S | G21: TH2 | H21: 10AS | I21: =VLOOKUP($H21,$D$2:$J$13,6,0) -> Thứ Ba (23/12) | J21: =VLOOKUP($H21,$D$2:$J$13,7,0) -> Thứ Năm (25/12) | K21: =COUNTIF('DS_Tong_12AS-AT-VH'!$B$9:$B$426,F21) -> 23 | L21: =D21-K21 -> 0 | M21: =VLOOKUP($G21,$L$5:$P$9,M$3,0) -> VĂN | N21: =VLOOKUP($G21,$L$5:$P$9,N$3,0) -> HÓA | O21: =VLOOKUP($G21,$L$5:$P$9,O$3,0) -> TOÁN | P21: =VLOOKUP($G21,$L$5:$P$9,P$3,0) -> SỬ | Q21: =Q20+K20 -> 100071 | R21: =Q21+K21-1 -> 100093 | S21: TỔ HỢP 2 (10AS1,2) | T21: =VLOOKUP($H21,$D$2:$G$13,2,0) -> NGÀY THI: 23+25/12/2025
A22: {=IF(C22="","",SUBTOTAL(3,$C$18:C22))} | B22: TỔ HỢP 3 (10AS3,4) | D22: 96 | K22: =SUM(K23:K26) -> 95 | L22: =SUM(L23:L26) -> 1 | M22: =VLOOKUP($G23,$L$5:$P$10,M$3,0) -> VĂN | N22: =VLOOKUP($G23,$L$5:$P$10,N$3,0) -> KT-PL | O22: =VLOOKUP($G23,$L$5:$P$10,O$3,0) -> TOÁN | P22: =VLOOKUP($G23,$L$5:$P$10,P$3,0) -> SỬ | T22: =VLOOKUP($H22,$D$2:$G$13,2,0) -> #N/A
A23: =IF(F23="","",SUBTOTAL(3,$F$18:F23)) -> 5 | B23: 1 | C23: 5A | D23: 24 | E23: 01.HN | F23: =C23&".S" -> 5A.S | G23: TH3 | H23: 10AS | I23: =VLOOKUP($H23,$D$2:$J$13,6,0) -> Thứ Ba (23/12) | J23: =VLOOKUP($H23,$D$2:$J$13,7,0) -> Thứ Năm (25/12) | K23: =COUNTIF('DS_Tong_12AS-AT-VH'!$B$9:$B$426,F23) -> 24 | L23: =D23-K23 -> 0 | M23: =VLOOKUP($G23,$L$5:$P$9,M$3,0) -> VĂN | N23: =VLOOKUP($G23,$L$5:$P$9,N$3,0) -> KT-PL | O23: =VLOOKUP($G23,$L$5:$P$9,O$3,0) -> TOÁN | P23: =VLOOKUP($G23,$L$5:$P$9,P$3,0) -> SỬ | Q23: =R21+1 -> 100094 | R23: =Q23+K23-1 -> 100117 | S23: TỔ HỢP 3 (10AS3,4) | T23: =VLOOKUP($H23,$D$2:$G$13,2,0) -> NGÀY THI: 23+25/12/2025
A24: =IF(F24="","",SUBTOTAL(3,$F$18:F24)) -> 6 | B24: 2 | C24: 6A | D24: 24 | F24: =C24&".S" -> 6A.S | G24: TH3 | H24: 10AS | I24: =VLOOKUP($H24,$D$2:$J$13,6,0) -> Thứ Ba (23/12) | J24: =VLOOKUP($H24,$D$2:$J$13,7,0) -> Thứ Năm (25/12) | K24: =COUNTIF('DS_Tong_12AS-AT-VH'!$B$9:$B$426,F24) -> 24 | L24: =D24-K24 -> 0 | M24: =VLOOKUP($G24,$L$5:$P$9,M$3,0) -> VĂN | N24: =VLOOKUP($G24,$L$5:$P$9,N$3,0) -> KT-PL | O24: =VLOOKUP($G24,$L$5:$P$9,O$3,0) -> TOÁN | P24: =VLOOKUP($G24,$L$5:$P$9,P$3,0) -> SỬ | Q24: =Q23+K23 -> 100118 | R24: =Q24+K24-1 -> 100141 | S24: TỔ HỢP 3 (10AS3,4) | T24: =VLOOKUP($H24,$D$2:$G$13,2,0) -> NGÀY THI: 23+25/12/2025
A25: =IF(F25="","",SUBTOTAL(3,$F$18:F25)) -> 7 | B25: 3 | C25: 9A | D25: 24 | F25: =C25&".S" -> 9A.S | G25: TH3 | H25: 10AS | I25: =VLOOKUP($H25,$D$2:$J$13,6,0) -> Thứ Ba (23/12) | J25: =VLOOKUP($H25,$D$2:$J$13,7,0) -> Thứ Năm (25/12) | K25: =COUNTIF('DS_Tong_12AS-AT-VH'!$B$9:$B$426,F25) -> 24 | L25: =D25-K25 -> 0 | M25: =VLOOKUP($G25,$L$5:$P$9,M$3,0) -> VĂN | N25: =VLOOKUP($G25,$L$5:$P$9,N$3,0) -> KT-PL | O25: =VLOOKUP($G25,$L$5:$P$9,O$3,0) -> TOÁN | P25: =VLOOKUP($G25,$L$5:$P$9,P$3,0) -> SỬ | Q25: =Q24+K24 -> 100142 | R25: =Q25+K25-1 -> 100165 | S25: TỔ HỢP 3 (10AS3,4) | T25: =VLOOKUP($H25,$D$2:$G$13,2,0) -> NGÀY THI: 23+25/12/2025
A26: =IF(F26="","",SUBTOTAL(3,$F$18:F26)) -> 8 | B26: 4 | C26: 10A | D26: 24 | F26: =C26&".S" -> 10A.S | G26: TH3 | H26: 10AS | I26: =VLOOKUP($H26,$D$2:$J$13,6,0) -> Thứ Ba (23/12) | J26: =VLOOKUP($H26,$D$2:$J$13,7,0) -> Thứ Năm (25/12) | K26: =COUNTIF('DS_Tong_12AS-AT-VH'!$B$9:$B$426,F26) -> 23 | L26: =D26-K26 -> 1 | M26: =VLOOKUP($G26,$L$5:$P$9,M$3,0) -> VĂN | N26: =VLOOKUP($G26,$L$5:$P$9,N$3,0) -> KT-PL | O26: =VLOOKUP($G26,$L$5:$P$9,O$3,0) -> TOÁN | P26: =VLOOKUP($G26,$L$5:$P$9,P$3,0) -> SỬ | Q26: =Q25+K25 -> 100166 | R26: =Q26+K26-1 -> 100188 | S26: TỔ HỢP 3 (10AS3,4) | T26: =VLOOKUP($H26,$D$2:$G$13,2,0) -> NGÀY THI: 23+25/12/2025
A27: {=IF(C27="","",SUBTOTAL(3,$C$18:C27))} | B27: TỔ HỢP 4 (10AS5,6,7) | D27: 143 | K27: =SUM(K28:K31) -> 96 | L27: =SUM(L28:L31) -> 0 | M27: =VLOOKUP($G28,$L$5:$P$10,M$3,0) -> VĂN | N27: =VLOOKUP($G28,$L$5:$P$10,N$3,0) -> LÝ | O27: =VLOOKUP($G28,$L$5:$P$10,O$3,0) -> TOÁN | P27: =VLOOKUP($G28,$L$5:$P$10,P$3,0) -> SỬ | T27: =VLOOKUP($H27,$D$2:$G$13,2,0) -> #N/A
A28: =IF(F28="","",SUBTOTAL(3,$F$18:F28)) -> 9 | B28: 1 | C28: 11A | D28: 24 | E28: 01.HN | F28: =C28&".S" -> 11A.S | G28: TH4 | H28: 10AS | I28: =VLOOKUP($H28,$D$2:$J$13,6,0) -> Thứ Ba (23/12) | J28: =VLOOKUP($H28,$D$2:$J$13,7,0) -> Thứ Năm (25/12) | K28: =COUNTIF('DS_Tong_12AS-AT-VH'!$B$9:$B$426,F28) -> 24 | L28: =D28-K28 -> 0 | M28: =VLOOKUP($G28,$L$5:$P$9,M$3,0) -> VĂN | N28: =VLOOKUP($G28,$L$5:$P$9,N$3,0) -> LÝ | O28: =VLOOKUP($G28,$L$5:$P$9,O$3,0) -> TOÁN | P28: =VLOOKUP($G28,$L$5:$P$9,P$3,0) -> SỬ | Q28: =R26+1 -> 100189 | R28: =Q28+K28-1 -> 100212 | S28: TỔ HỢP 4 (10AS5,6,7) | T28: =VLOOKUP($H28,$D$2:$G$13,2,0) -> NGÀY THI: 23+25/12/2025
A29: =IF(F29="","",SUBTOTAL(3,$F$18:F29)) -> 10 | B29: 2 | C29: 12A | D29: 24 | F29: =C29&".S" -> 12A.S | G29: TH4 | H29: 10AS | I29: =VLOOKUP($H29,$D$2:$J$13,6,0) -> Thứ Ba (23/12) | J29: =VLOOKUP($H29,$D$2:$J$13,7,0) -> Thứ Năm (25/12) | K29: =COUNTIF('DS_Tong_12AS-AT-VH'!$B$9:$B$426,F29) -> 24 | L29: =D29-K29 -> 0 | M29: =VLOOKUP($G29,$L$5:$P$9,M$3,0) -> VĂN | N29: =VLOOKUP($G29,$L$5:$P$9,N$3,0) -> LÝ | O29: =VLOOKUP($G29,$L$5:$P$9,O$3,0) -> TOÁN | P29: =VLOOKUP($G29,$L$5:$P$9,P$3,0) -> SỬ | Q29: =Q28+K28 -> 100213 | R29: =Q29+K29-1 -> 100236 | S29: TỔ HỢP 4 (10AS5,6,7) | T29: =VLOOKUP($H29,$D$2:$G$13,2,0) -> NGÀY THI: 23+25/12/2025
A30: =IF(F30="","",SUBTOTAL(3,$F$18:F30)) -> 11 | B30: 3 | C30: 13A | D30: 24 | F30: =C30&".S" -> 13A.S | G30: TH4 | H30: 10AS | I30: =VLOOKUP($H30,$D$2:$J$13,6,0) -> Thứ Ba (23/12) | J30: =VLOOKUP($H30,$D$2:$J$13,7,0) -> Thứ Năm (25/12) | K30: =COUNTIF('DS_Tong_12AS-AT-VH'!$B$9:$B$426,F30) -> 24 | L30: =D30-K30 -> 0 | M30: =VLOOKUP($G30,$L$5:$P$9,M$3,0) -> VĂN | N30: =VLOOKUP($G30,$L$5:$P$9,N$3,0) -> LÝ | O30: =VLOOKUP($G30,$L$5:$P$9,O$3,0) -> TOÁN | P30: =VLOOKUP($G30,$L$5:$P$9,P$3,0) -> SỬ | Q30: =Q29+K29 -> 100237 | R30: =Q30+K30-1 -> 100260 | S30: TỔ HỢP 4 (10AS5,6,7) | T30: =VLOOKUP($H30,$D$2:$G$13,2,0) -> NGÀY THI: 23+25/12/2025
A31: =IF(F31="","",SUBTOTAL(3,$F$18:F31)) -> 12 | B31: 4 | C31: 14A | D31: 24 | F31: =C31&".S" -> 14A.S | G31: TH4 | H31: 10AS | I31: =VLOOKUP($H31,$D$2:$J$13,6,0) -> Thứ Ba (23/12) | J31: =VLOOKUP($H31,$D$2:$J$13,7,0) -> Thứ Năm (25/12) | K31: =COUNTIF('DS_Tong_12AS-AT-VH'!$B$9:$B$426,F31) -> 24 | L31: =D31-K31 -> 0 | M31: =VLOOKUP($G31,$L$5:$P$9,M$3,0) -> VĂN | N31: =VLOOKUP($G31,$L$5:$P$9,N$3,0) -> LÝ | O31: =VLOOKUP($G31,$L$5:$P$9,O$3,0) -> TOÁN | P31: =VLOOKUP($G31,$L$5:$P$9,P$3,0) -> SỬ | Q31: =Q30+K30 -> 100261 | R31: =Q31+K31-1 -> 100284 | S31: TỔ HỢP 4 (10AS5,6,7) | T31: =VLOOKUP($H31,$D$2:$G$13,2,0) -> NGÀY THI: 23+25/12/2025
A32: =IF(F32="","",SUBTOTAL(3,$F$18:F32)) -> 13 | B32: 5 | C32: 2B | D32: 24 | F32: =C32&".S" -> 2B.S | G32: TH4 | H32: 10AS | I32: =VLOOKUP($H32,$D$2:$J$13,6,0) -> Thứ Ba (23/12) | J32: =VLOOKUP($H32,$D$2:$J$13,7,0) -> Thứ Năm (25/12) | K32: =COUNTIF('DS_Tong_12AS-AT-VH'!$B$9:$B$426,F32) -> 24 | L32: =D32-K32 -> 0 | M32: =VLOOKUP($G32,$L$5:$P$9,M$3,0) -> VĂN | N32: =VLOOKUP($G32,$L$5:$P$9,N$3,0) -> LÝ | O32: =VLOOKUP($G32,$L$5:$P$9,O$3,0) -> TOÁN | P32: =VLOOKUP($G32,$L$5:$P$9,P$3,0) -> SỬ | Q32: =Q31+K31 -> 100285 | R32: =Q32+K32-1 -> 100308 | S32: TỔ HỢP 4 (10AS5,6,7) | T32: =VLOOKUP($H32,$D$2:$G$13,2,0) -> NGÀY THI: 23+25/12/2025
A33: =IF(F33="","",SUBTOTAL(3,$F$18:F33)) -> 14 | B33: 6 | C33: 3B | D33: 23 | F33: =C33&".S" -> 3B.S | G33: TH4 | H33: 10AS | I33: =VLOOKUP($H33,$D$2:$J$13,6,0) -> Thứ Ba (23/12) | J33: =VLOOKUP($H33,$D$2:$J$13,7,0) -> Thứ Năm (25/12) | K33: =COUNTIF('DS_Tong_12AS-AT-VH'!$B$9:$B$426,F33) -> 23 | L33: =D33-K33 -> 0 | M33: =VLOOKUP($G33,$L$5:$P$9,M$3,0) -> VĂN | N33: =VLOOKUP($G33,$L$5:$P$9,N$3,0) -> LÝ | O33: =VLOOKUP($G33,$L$5:$P$9,O$3,0) -> TOÁN | P33: =VLOOKUP($G33,$L$5:$P$9,P$3,0) -> SỬ | Q33: =Q32+K32 -> 100309 | R33: =Q33+K33-1 -> 100331 | S33: TỔ HỢP 4 (10AS5,6,7) | T33: =VLOOKUP($H33,$D$2:$G$13,2,0) -> NGÀY THI: 23+25/12/2025
B34: KHỐI 10AT | C34: 3 phòng | D34: 87 | T34: =VLOOKUP($H34,$D$2:$G$13,2,0) -> #N/A
B35: TỔ HỢP 4 (10AT1,2) | D35: 87 | M35: =VLOOKUP($G36,$L$5:$P$10,M$3,0) -> VĂN | N35: =VLOOKUP($G36,$L$5:$P$10,N$3,0) -> LÝ | O35: =VLOOKUP($G36,$L$5:$P$10,O$3,0) -> TOÁN | P35: =VLOOKUP($G36,$L$5:$P$10,P$3,0) -> SỬ | T35: =VLOOKUP($H35,$D$2:$G$13,2,0) -> #N/A
A36: =IF(F36="","",SUBTOTAL(3,$F$18:F36)) -> 15 | B36: 1 | C36: 7B | D36: 29 | F36: =C36&".T" -> 7B.T | G36: TH4 | H36: 10AT | I36: =VLOOKUP($H36,$D$2:$J$13,6,0) -> Thứ Hai (22/12) | J36: =VLOOKUP($H36,$D$2:$J$13,7,0) -> Thứ Ba (23/12) | K36: =COUNTIF('DS_Tong_12AS-AT-VH'!$B$9:$B$426,F36) -> 29 | L36: =D36-K36 -> 0 | M36: =VLOOKUP($G36,$L$5:$P$9,M$3,0) -> VĂN | N36: =VLOOKUP($G36,$L$5:$P$9,N$3,0) -> LÝ | O36: =VLOOKUP($G36,$L$5:$P$9,O$3,0) -> TOÁN | P36: =VLOOKUP($G36,$L$5:$P$9,P$3,0) -> SỬ | Q36: =R33+1 -> 100332 | R36: =Q36+K36-1 -> 100360 | S36: TỔ HỢP 4 (10AT1,2) | T36: =VLOOKUP($H36,$D$2:$G$13,2,0) -> NGÀY THI: 22+23/12/2025
A37: =IF(F37="","",SUBTOTAL(3,$F$18:F37)) -> 16 | B37: 2 | C37: 8B | D37: 29 | F37: =C37&".T" -> 8B.T | G37: TH4 | H37: 10AT | I37: =VLOOKUP($H37,$D$2:$J$13,6,0) -> Thứ Hai (22/12) | J37: =VLOOKUP($H37,$D$2:$J$13,7,0) -> Thứ Ba (23/12) | K37: =COUNTIF('DS_Tong_12AS-AT-VH'!$B$9:$B$426,F37) -> 29 | L37: =D37-K37 -> 0 | M37: =VLOOKUP($G37,$L$5:$P$9,M$3,0) -> VĂN | N37: =VLOOKUP($G37,$L$5:$P$9,N$3,0) -> LÝ | O37: =VLOOKUP($G37,$L$5:$P$9,O$3,0) -> TOÁN | P37: =VLOOKUP($G37,$L$5:$P$9,P$3,0) -> SỬ | Q37: =Q36+K36 -> 100361 | R37: =Q37+K37-1 -> 100389 | S37: TỔ HỢP 4 (10AT1,2) | T37: =VLOOKUP($H37,$D$2:$G$13,2,0) -> NGÀY THI: 22+23/12/2025
A38: =IF(F38="","",SUBTOTAL(3,$F$18:F38)) -> 17 | B38: 3 | C38: 9B | D38: 29 | F38: =C38&".T" -> 9B.T | G38: TH4 | H38: 10AT | I38: =VLOOKUP($H38,$D$2:$J$13,6,0) -> Thứ Hai (22/12) | J38: =VLOOKUP($H38,$D$2:$J$13,7,0) -> Thứ Ba (23/12) | K38: =COUNTIF('DS_Tong_12AS-AT-VH'!$B$9:$B$426,F38) -> 29 | L38: =D38-K38 -> 0 | M38: =VLOOKUP($G38,$L$5:$P$9,M$3,0) -> VĂN | N38: =VLOOKUP($G38,$L$5:$P$9,N$3,0) -> LÝ | O38: =VLOOKUP($G38,$L$5:$P$9,O$3,0) -> TOÁN | P38: =VLOOKUP($G38,$L$5:$P$9,P$3,0) -> SỬ | Q38: =Q37+K37 -> 100390 | R38: =Q38+K38-1 -> 100418 | S38: TỔ HỢP 4 (10AT1,2) | T38: =VLOOKUP($H38,$D$2:$G$13,2,0) -> NGÀY THI: 22+23/12/2025
B39: KHỐI 11AS | C39: 5 phòng | D39: 142 | T39: =VLOOKUP($H39,$D$2:$G$13,2,0) -> #N/A
B40: TỔ HỢP 4 (11AS1,2,3) | D40: 142 | M40: =VLOOKUP($G41,$L$5:$P$10,M$3,0) -> VĂN | N40: SINH | O40: =VLOOKUP($G41,$L$5:$P$10,O$3,0) -> TOÁN | P40: =VLOOKUP($G41,$L$5:$P$10,P$3,0) -> SỬ | T40: =VLOOKUP($H40,$D$2:$G$13,2,0) -> #N/A
...

Sheet DS_Tong_12AS-AT-VH
A1: UBND THÀNH PHỐ THỦ ĐỨC | G1: CỘNG HÒA XÃ HỘI CHỦ NGHĨA VIỆT NAM | N1: TH1 | O1: LÝ
A2: TRUNG TÂM GDNN - GDTX | G2: Độc lập - Tự do - Hạnh phúc | N2: TH2 | O2: HÓA
N3: TH3 | O3: KT-PL
A6: Stt | B6: P.thi.Buổi | C6: TH | D6: Phòng thi | E6: SBD | F6: Họ | G6: Tên | H6: Lớp | I6: Ghi chú | J6: MÔN THI | O6: Khuyết tật | P6: Mức độ | Q6: Nghỉ học (NgiH) | R6: Chưa đóng HP
J7: Thứ Hai (23/12) | L7: Thứ Tư (25/12) | O7: 6 | P7: 7 | Q7: 8 | R7: 9
A8: 1 | B8: 2 | C8: 3 | D8: 4 | E8: 5 | F8: 6 | G8: 7 | H8: 8 | I8: 9 | J8: VĂN | K8: LÝ | L8: TOÁN | M8: SỬ | U8: Nghỉ học | V8: =COUNTIF($V$9:$V$3025,"hp") -> 0
A9: 1 | B9: =RIGHT(D9,LEN(D9)-2)&"."&LEFT(N9,1) -> 1A.S | C9: TH2 | D9: P.1A | E9: 100001 | F9: Nguyễn Hoài | G9: An | H9: 10AS1 | N9: Sáng | O9: 0 | P9: 0 | Q9: =U9 -> 0 | T9: =TRIM(F9&" "&G9&"_"&H9) -> Nguyễn Hoài An_10AS1 | U9: {=IFERROR(VLOOKUP($T9,'Nghi hoc T12'!$H$7:$I$160,2,0),0)} -> 0 | V9: =IFERROR(VLOOKUP($T9,No_HP!$B$2:$C$514,2,0),0) -> 0 | W9: =I9 -> 0 | X9: =O9 -> 0 | Y9: =P9 -> 0
A10: 2 | B10: =RIGHT(D10,LEN(D10)-2)&"."&LEFT(N10,1) -> 1A.S | C10: TH2 | D10: P.1A | E10: 100002 | F10: Nguyễn Hoàng Gia | G10: An | H10: 10AS1 | N10: Sáng | O10: 0 | P10: 0 | Q10: =U10 -> 0 | T10: =TRIM(F10&" "&G10&"_"&H10) -> Nguyễn Hoàng Gia An_10AS1 | U10: {=IFERROR(VLOOKUP($T10,'Nghi hoc T12'!$H$7:$I$160,2,0),0)} -> 0 | V10: =IFERROR(VLOOKUP($T10,No_HP!$B$2:$C$514,2,0),0) -> 0 | W10: =I10 -> 0 | X10: =O10 -> 0 | Y10: =P10 -> 0
A11: 3 | B11: =RIGHT(D11,LEN(D11)-2)&"."&LEFT(N11,1) -> 1A.S | C11: TH2 | D11: P.1A | E11: 100003 | F11: Trần Xuân Thái | G11: An | H11: 10AS2 | N11: Sáng | O11: 0 | P11: 0 | Q11: =U11 -> 0 | T11: =TRIM(F11&" "&G11&"_"&H11) -> Trần Xuân Thái An_10AS2 | U11: {=IFERROR(VLOOKUP($T11,'Nghi hoc T12'!$H$7:$I$160,2,0),0)} -> 0 | V11: =IFERROR(VLOOKUP($T11,No_HP!$B$2:$C$514,2,0),0) -> 0 | W11: =I11 -> 0 | X11: =O11 -> 0 | Y11: =P11 -> 0
A12: 4 | B12: =RIGHT(D12,LEN(D12)-2)&"."&LEFT(N12,1) -> 1A.S | C12: TH2 | D12: P.1A | E12: 100004 | F12: Ngô Quốc | G12: Anh | H12: 10AS1 | N12: Sáng | O12: 0 | P12: 0 | Q12: =U12 -> 0 | T12: =TRIM(F12&" "&G12&"_"&H12) -> Ngô Quốc Anh_10AS1 | U12: {=IFERROR(VLOOKUP($T12,'Nghi hoc T12'!$H$7:$I$160,2,0),0)} -> 0 | V12: =IFERROR(VLOOKUP($T12,No_HP!$B$2:$C$514,2,0),0) -> 0 | W12: =I12 -> 0 | X12: =O12 -> 0 | Y12: =P12 -> 0
