Workbook

Sheet 1_Coppy_Tke Pthi dan
A1: COPPY DS THI TẬP TRUNG | K1: 5 | L1: 6 | M1: 7 | N1: 8 | O1: 9 | P1: 10
C2: ="LỚP "&D2&" -" -> LỚP 12AS - | D2: 12AS | E2: NGÀY THI: 22+24/12/2025 | H2: SÁNG | I2: Thứ Hai (22/12) | J2: Thứ Tư (24/12) | K2: Đ.chiếu DS trộn | L2: Chênh lệch
C3: ="LỚP "&D3&" -" -> LỚP 12KT - | D3: 12KT | E3: NGÀY THI: 22+24/12/2025 | H3: SÁNG | I3: Thứ Hai (22/12) | J3: Thứ Tư (24/12) | M3: 2 | N3: 3 | O3: 4 | P3: 5
C4: ="LỚP "&D4&" -" -> LỚP 10VH - | D4: 10VH | E4: NGÀY THI: 22+24/12/2025 | H4: CHIỀU | I4: Thứ Hai (22/12) | J4: Thứ Tư (24/12)
C5: ="LỚP "&D5&" -" -> LỚP 10KT - | D5: 10KT | E5: NGÀY THI: 22+24/12/2025 | H5: CHIỀU | I5: Thứ Hai (22/12) | J5: Thứ Tư (24/12) | L5: TH1 | M5: VĂN | N5: LÝ | O5: TOÁN | P5: SỬ
C6: ="LỚP "&D6&" -" -> LỚP 12AT - | D6: 12AT | E6: NGÀY THI: 22+23/12/2025 | H6: TỐI | I6: Thứ Hai (22/12) | J6: Thứ Ba (23/12) | L6: TH2 | M6: VĂN | N6: HÓA | O6: TOÁN | P6: SỬ
C7: ="LỚP "&D7&" -" -> LỚP 12VH - | D7: 12VH | E7: NGÀY THI: 22+23/12/2025 | H7: TỐI | I7: Thứ Hai (22/12) | J7: Thứ Ba (23/12) | L7: TH3 | M7: VĂN | N7: KT-PL | O7: TOÁN | P7: SỬ
C8: ="LỚP "&D8&" -" -> LỚP 10AT - | D8: 10AT | E8: NGÀY THI: 22+23/12/2025 | H8: TỐI | I8: Thứ Hai (22/12) | J8: Thứ Ba (23/12) | L8: TH4 | M8: VĂN | N8: LÝ | O8: TOÁN | P8: SỬ
C9: ="LỚP "&D9&" -" -> LỚP 11AT - | D9: 11AT | E9: NGÀY THI: 22+23/12/2025 | H9: TỐI | I9: Thứ Hai (22/12) | J9: Thứ Ba (23/12) | L9: TH5 | M9: VĂN | N9: KT-PL | O9: TOÁN | P9: SỬ
C10: ="LỚP "&D10&" -" -> LỚP 10AS - | D10: 10AS | E10: NGÀY THI: 23+25/12/2025 | H10: SÁNG | I10: Thứ Ba (23/12) | J10: Thứ Năm (25/12) | L10: TH4 | M10: VĂN | N10: SINH | O10: TOÁN | P10: SỬ
C11: ="LỚP "&D11&" -" -> LỚP 11AS - | D11: 11AS | E11: NGÀY THI: 23+25/12/2025 | H11: SÁNG | I11: Thứ Ba (23/12) | J11: Thứ Năm (25/12)
C12: ="LỚP "&D12&" -" -> LỚP 11VH - | D12: 11VH | E12: NGÀY THI: 23+25/12/2025 | H12: CHIỀU | I12: Thứ Ba (23/12) | J12: Thứ Năm (25/12)
C13: ="LỚP "&D13&" -" -> LỚP 11KT - | D13: 11KT | E13: NGÀY THI: 23+25/12/2025 | H13: CHIỀU | I13: Thứ Ba (23/12) | J13: Thứ Năm (25/12)
A14: Cột 1 | B14: Cột 2 | C14: Cột 3 | D14: Cột 4 | E14: Cột 5 | F14: Cột 6 | G14: Cột 7 | H14: Cột 8 | I14: Cột 9 | J14: Cột 10 | K14: Cột 11 | L14: Cột 12 | M14: Cột 13 | N14: Cột 14 | O14: Cột 15 | P14: Cột 16 | Q14: Cột 17 | R14: Cột 18 | S14: Cột 19 | T14: Cột 20
B15: KH/Phòng
B16: KHỐI 10AS | C16: 14 phòng | D16: 382
B17: TỔ HỢP 2 (10AS1,2) | D17: 93 | K17: 93 | L17: =SUM(L18:L21) -> 0 | M17: =VLOOKUP($G18,$L$5:$P$10,M$3,0) -> VĂN | N17: =VLOOKUP($G18,$L$5:$P$10,N$3,0) -> HÓA | O17: =VLOOKUP($G18,$L$5:$P$10,O$3,0) -> TOÁN | P17: =VLOOKUP($G18,$L$5:$P$10,P$3,0) -> SỬ | Q17: Cột 15 | R17: Cột 16 | S17: Cột 17
A18: {=IF(F18="","",SUBTOTAL(3,$F$18:F18))} -> 1 | B18: 1 | C18: 1A | D18: 24 | F18: =C18&".S" -> 1A.S | G18: TH2 | H18: 10AS | I18: =VLOOKUP($H18,$D$2:$J$13,6,0) -> Thứ Ba (23/12) | J18: =VLOOKUP($H18,$D$2:$J$13,7,0) -> Thứ Năm (25/12) | K18: 24 | L18: =D18-K18 -> 0 | M18: =VLOOKUP($G18,$L$5:$P$9,M$3,0) -> VĂN | N18: =VLOOKUP($G18,$L$5:$P$9,N$3,0) -> HÓA | O18: =VLOOKUP($G18,$L$5:$P$9,O$3,0) -> TOÁN | P18: =VLOOKUP($G18,$L$5:$P$9,P$3,0) -> SỬ | Q18: 100001 | R18: =Q18+K18-1 -> 100024 | S18: TỔ HỢP 2 (10AS1,2) | T18: NGÀY THI: 23+25/12/2025
A19: {=IF(F19="","",SUBTOTAL(3,$F$18:F19))} -> 2 | B19: 2 | C19: 2A | D19: 23 | F19: =C19&".S" -> 2A.S | G19: TH2 | H19: 10AS | I19: =VLOOKUP($H19,$D$2:$J$13,6,0) -> Thứ Ba (23/12) | J19: =VLOOKUP($H19,$D$2:$J$13,7,0) -> Thứ Năm (25/12) | K19: 23 | L19: =D19-K19 -> 0 | M19: =VLOOKUP($G19,$L$5:$P$9,M$3,0) -> VĂN | N19: =VLOOKUP($G19,$L$5:$P$9,N$3,0) -> HÓA | O19: =VLOOKUP($G19,$L$5:$P$9,O$3,0) -> TOÁN | P19: =VLOOKUP($G19,$L$5:$P$9,P$3,0) -> SỬ | Q19: =Q18+K18 -> 100025 | R19: =Q19+K19-1 -> 100047 | S19: TỔ HỢP 2 (10AS1,2) | T19: NGÀY THI: 23+25/12/2025
A20: {=IF(F20="","",SUBTOTAL(3,$F$18:F20))} -> 3 | B20: 3 | C20: 3A | D20: 23 | F20: =C20&".S" -> 3A.S | G20: TH2 | H20: 10AS | I20: =VLOOKUP($H20,$D$2:$J$13,6,0) -> Thứ Ba (23/12) | J20: =VLOOKUP($H20,$D$2:$J$13,7,0) -> Thứ Năm (25/12) | K20: 23 | L20: =D20-K20 -> 0 | M20: =VLOOKUP($G20,$L$5:$P$9,M$3,0) -> VĂN | N20: =VLOOKUP($G20,$L$5:$P$9,N$3,0) -> HÓA | O20: =VLOOKUP($G20,$L$5:$P$9,O$3,0) -> TOÁN | P20: =VLOOKUP($G20,$L$5:$P$9,P$3,0) -> SỬ | Q20: =Q19+K19 -> 100048 | R20: =Q20+K20-1 -> 100070 | S20: TỔ HỢP 2 (10AS1,2) | T20: NGÀY THI: 23+25/12/2025
A21: {=IF(F21="","",SUBTOTAL(3,$F$18:F21))} -> 4 | B21: 4 | C21: 4A | D21: 23 | F21: =C21&".S" -> 4A.S | G21: TH2 | H21: 10AS | I21: =VLOOKUP($H21,$D$2:$J$13,6,0) -> Thứ Ba (23/12) | J21: =VLOOKUP($H21,$D$2:$J$13,7,0) -> Thứ Năm (25/12) | K21: 23 | L21: =D21-K21 -> 0 | M21: =VLOOKUP($G21,$L$5:$P$9,M$3,0) -> VĂN | N21: =VLOOKUP($G21,$L$5:$P$9,N$3,0) -> HÓA | O21: =VLOOKUP($G21,$L$5:$P$9,O$3,0) -> TOÁN | P21: =VLOOKUP($G21,$L$5:$P$9,P$3,0) -> SỬ | Q21: =Q20+K20 -> 100071 | R21: =Q21+K21-1 -> 100093 | S21: TỔ HỢP 2 (10AS1,2) | T21: NGÀY THI: 23+25/12/2025
A22: {=IF(F22="","",SUBTOTAL(3,$F$18:F22))} | B22: TỔ HỢP 3 (10AS3,4) | D22: 96 | K22: 95 | L22: =SUM(L23:L26) -> 1 | M22: =VLOOKUP($G23,$L$5:$P$10,M$3,0) -> VĂN | N22: =VLOOKUP($G23,$L$5:$P$10,N$3,0) -> KT-PL | O22: =VLOOKUP($G23,$L$5:$P$10,O$3,0) -> TOÁN | P22: =VLOOKUP($G23,$L$5:$P$10,P$3,0) -> SỬ | T22: #N/A
A23: {=IF(F23="","",SUBTOTAL(3,$F$18:F23))} -> 5 | B23: 1 | C23: 5A | D23: 24 | E23: 01.HN | F23: =C23&".S" -> 5A.S | G23: TH3 | H23: 10AS | I23: =VLOOKUP($H23,$D$2:$J$13,6,0) -> Thứ Ba (23/12) | J23: =VLOOKUP($H23,$D$2:$J$13,7,0) -> Thứ Năm (25/12) | K23: 24 | L23: =D23-K23 -> 0 | M23: =VLOOKUP($G23,$L$5:$P$9,M$3,0) -> VĂN | N23: =VLOOKUP($G23,$L$5:$P$9,N$3,0) -> KT-PL | O23: =VLOOKUP($G23,$L$5:$P$9,O$3,0) -> TOÁN | P23: =VLOOKUP($G23,$L$5:$P$9,P$3,0) -> SỬ | Q23: =R21+1 -> 100094 | R23: =Q23+K23-1 -> 100117 | S23: TỔ HỢP 3 (10AS3,4) | T23: NGÀY THI: 23+25/12/2025
A24: {=IF(F24="","",SUBTOTAL(3,$F$18:F24))} -> 6 | B24: 2 | C24: 6A | D24: 24 | F24: =C24&".S" -> 6A.S | G24: TH3 | H24: 10AS | I24: =VLOOKUP($H24,$D$2:$J$13,6,0) -> Thứ Ba (23/12) | J24: =VLOOKUP($H24,$D$2:$J$13,7,0) -> Thứ Năm (25/12) | K24: 24 | L24: =D24-K24 -> 0 | M24: =VLOOKUP($G24,$L$5:$P$9,M$3,0) -> VĂN | N24: =VLOOKUP($G24,$L$5:$P$9,N$3,0) -> KT-PL | O24: =VLOOKUP($G24,$L$5:$P$9,O$3,0) -> TOÁN | P24: =VLOOKUP($G24,$L$5:$P$9,P$3,0) -> SỬ | Q24: =Q23+K23 -> 100118 | R24: =Q24+K24-1 -> 100141 | S24: TỔ HỢP 3 (10AS3,4) | T24: NGÀY THI: 23+25/12/2025
A25: {=IF(F25="","",SUBTOTAL(3,$F$18:F25))} -> 7 | B25: 3 | C25: 9A | D25: 24 | F25: =C25&".S" -> 9A.S | G25: TH3 | H25: 10AS | I25: =VLOOKUP($H25,$D$2:$J$13,6,0) -> Thứ Ba (23/12) | J25: =VLOOKUP($H25,$D$2:$J$13,7,0) -> Thứ Năm (25/12) | K25: 24 | L25: =D25-K25 -> 0 | M25: =VLOOKUP($G25,$L$5:$P$9,M$3,0) -> VĂN | N25: =VLOOKUP($G25,$L$5:$P$9,N$3,0) -> KT-PL | O25: =VLOOKUP($G25,$L$5:$P$9,O$3,0) -> TOÁN | P25: =VLOOKUP($G25,$L$5:$P$9,P$3,0) -> SỬ | Q25: =Q24+K24 -> 100142 | R25: =Q25+K25-1 -> 100165 | S25: TỔ HỢP 3 (10AS3,4) | T25: NGÀY THI: 23+25/12/2025
A26: {=IF(F26="","",SUBTOTAL(3,$F$18:F26))} -> 8 | B26: 4 | C26: 10A | D26: 24 | F26: =C26&".S" -> 10A.S | G26: TH3 | H26: 10AS | I26: =VLOOKUP($H26,$D$2:$J$13,6,0) -> Thứ Ba (23/12) | J26: =VLOOKUP($H26,$D$2:$J$13,7,0) -> Thứ Năm (25/12) | K26: 23 | L26: =D26-K26 -> 1 | M26: =VLOOKUP($G26,$L$5:$P$9,M$3,0) -> VĂN | N26: =VLOOKUP($G26,$L$5:$P$9,N$3,0) -> KT-PL | O26: =VLOOKUP($G26,$L$5:$P$9,O$3,0) -> TOÁN | P26: =VLOOKUP($G26,$L$5:$P$9,P$3,0) -> SỬ | Q26: =Q25+K25 -> 100166 | R26: =Q26+K26-1 -> 100188 | S26: TỔ HỢP 3 (10AS3,4) | T26: NGÀY THI: 23+25/12/2025
A27: {=IF(F27="","",SUBTOTAL(3,$F$18:F27))} | B27: TỔ HỢP 4 (10AS5,6,7) | D27: 143 | K27: 96 | L27: =SUM(L28:L31) -> 0 | M27: =VLOOKUP($G28,$L$5:$P$10,M$3,0) -> VĂN | N27: =VLOOKUP($G28,$L$5:$P$10,N$3,0) -> LÝ | O27: =VLOOKUP($G28,$L$5:$P$10,O$3,0) -> TOÁN | P27: =VLOOKUP($G28,$L$5:$P$10,P$3,0) -> SỬ | T27: #N/A
A28: {=IF(F28="","",SUBTOTAL(3,$F$18:F28))} -> 9 | B28: 1 | C28: 11A | D28: 24 | E28: 01.HN | F28: =C28&".S" -> 11A.S | G28: TH4 | H28: 10AS | I28: =VLOOKUP($H28,$D$2:$J$13,6,0) -> Thứ Ba (23/12) | J28: =VLOOKUP($H28,$D$2:$J$13,7,0) -> Thứ Năm (25/12) | K28: 24 | L28: =D28-K28 -> 0 | M28: =VLOOKUP($G28,$L$5:$P$9,M$3,0) -> VĂN | N28: =VLOOKUP($G28,$L$5:$P$9,N$3,0) -> LÝ | O28: =VLOOKUP($G28,$L$5:$P$9,O$3,0) -> TOÁN | P28: =VLOOKUP($G28,$L$5:$P$9,P$3,0) -> SỬ | Q28: =R26+1 -> 100189 | R28: =Q28+K28-1 -> 100212 | S28: TỔ HỢP 4 (10AS5,6,7) | T28: NGÀY THI: 23+25/12/2025
A29: {=IF(F29="","",SUBTOTAL(3,$F$18:F29))} -> 10 | B29: 2 | C29: 12A | D29: 24 | F29: =C29&".S" -> 12A.S | G29: TH4 | H29: 10AS | I29: =VLOOKUP($H29,$D$2:$J$13,6,0) -> Thứ Ba (23/12) | J29: =VLOOKUP($H29,$D$2:$J$13,7,0) -> Thứ Năm (25/12) | K29: 24 | L29: =D29-K29 -> 0 | M29: =VLOOKUP($G29,$L$5:$P$9,M$3,0) -> VĂN | N29: =VLOOKUP($G29,$L$5:$P$9,N$3,0) -> LÝ | O29: =VLOOKUP($G29,$L$5:$P$9,O$3,0) -> TOÁN | P29: =VLOOKUP($G29,$L$5:$P$9,P$3,0) -> SỬ | Q29: =Q28+K28 -> 100213 | R29: =Q29+K29-1 -> 100236 | S29: TỔ HỢP 4 (10AS5,6,7) | T29: NGÀY THI: 23+25/12/2025
A30: {=IF(F30="","",SUBTOTAL(3,$F$18:F30))} -> 11 | B30: 3 | C30: 13A | D30: 24 | F30: =C30&".S" -> 13A.S | G30: TH4 | H30: 10AS | I30: =VLOOKUP($H30,$D$2:$J$13,6,0) -> Thứ Ba (23/12) | J30: =VLOOKUP($H30,$D$2:$J$13,7,0) -> Thứ Năm (25/12) | K30: 24 | L30: =D30-K30 -> 0 | M30: =VLOOKUP($G30,$L$5:$P$9,M$3,0) -> VĂN | N30: =VLOOKUP($G30,$L$5:$P$9,N$3,0) -> LÝ | O30: =VLOOKUP($G30,$L$5:$P$9,O$3,0) -> TOÁN | P30: =VLOOKUP($G30,$L$5:$P$9,P$3,0) -> SỬ | Q30: =Q29+K29 -> 100237 | R30: =Q30+K30-1 -> 100260 | S30: TỔ HỢP 4 (10AS5,6,7) | T30: NGÀY THI: 23+25/12/2025
A31: {=IF(F31="","",SUBTOTAL(3,$F$18:F31))} -> 12 | B31: 4 | C31: 14A | D31: 24 | F31: =C31&".S" -> 14A.S | G31: TH4 | H31: 10AS | I31: =VLOOKUP($H31,$D$2:$J$13,6,0) -> Thứ Ba (23/12) | J31: =VLOOKUP($H31,$D$2:$J$13,7,0) -> Thứ Năm (25/12) | K31: 24 | L31: =D31-K31 -> 0 | M31: =VLOOKUP($G31,$L$5:$P$9,M$3,0) -> VĂN | N31: =VLOOKUP($G31,$L$5:$P$9,N$3,0) -> LÝ | O31: =VLOOKUP($G31,$L$5:$P$9,O$3,0) -> TOÁN | P31: =VLOOKUP($G31,$L$5:$P$9,P$3,0) -> SỬ | Q31: =Q30+K30 -> 100261 | R31: =Q31+K31-1 -> 100284 | S31: TỔ HỢP 4 (10AS5,6,7) | T31: NGÀY THI: 23+25/12/2025
A32: {=IF(F32="","",SUBTOTAL(3,$F$18:F32))} -> 13 | B32: 5 | C32: 2B | D32: 24 | F32: =C32&".S" -> 2B.S | G32: TH4 | H32: 10AS | I32: =VLOOKUP($H32,$D$2:$J$13,6,0) -> Thứ Ba (23/12) | J32: =VLOOKUP($H32,$D$2:$J$13,7,0) -> Thứ Năm (25/12) | K32: 24 | L32: =D32-K32 -> 0 | M32: =VLOOKUP($G32,$L$5:$P$9,M$3,0) -> VĂN | N32: =VLOOKUP($G32,$L$5:$P$9,N$3,0) -> LÝ | O32: =VLOOKUP($G32,$L$5:$P$9,O$3,0) -> TOÁN | P32: =VLOOKUP($G32,$L$5:$P$9,P$3,0) -> SỬ | Q32: =Q31+K31 -> 100285 | R32: =Q32+K32-1 -> 100308 | S32: TỔ HỢP 4 (10AS5,6,7) | T32: NGÀY THI: 23+25/12/2025
A33: {=IF(F33="","",SUBTOTAL(3,$F$18:F33))} -> 14 | B33: 6 | C33: 3B | D33: 23 | F33: =C33&".S" -> 3B.S | G33: TH4 | H33: 10AS | I33: =VLOOKUP($H33,$D$2:$J$13,6,0) -> Thứ Ba (23/12) | J33: =VLOOKUP($H33,$D$2:$J$13,7,0) -> Thứ Năm (25/12) | K33: 23 | L33: =D33-K33 -> 0 | M33: =VLOOKUP($G33,$L$5:$P$9,M$3,0) -> VĂN | N33: =VLOOKUP($G33,$L$5:$P$9,N$3,0) -> LÝ | O33: =VLOOKUP($G33,$L$5:$P$9,O$3,0) -> TOÁN | P33: =VLOOKUP($G33,$L$5:$P$9,P$3,0) -> SỬ | Q33: =Q32+K32 -> 100309 | R33: =Q33+K33-1 -> 100331 | S33: TỔ HỢP 4 (10AS5,6,7) | T33: NGÀY THI: 23+25/12/2025
A34: {=IF(F34="","",SUBTOTAL(3,$F$18:F34))} | B34: KHỐI 10AT | C34: 3 phòng | D34: 87 | T34: #N/A
A35: {=IF(F35="","",SUBTOTAL(3,$F$18:F35))} | B35: TỔ HỢP 4 (10AT1,2) | D35: 87 | M35: =VLOOKUP($G36,$L$5:$P$10,M$3,0) -> VĂN | N35: =VLOOKUP($G36,$L$5:$P$10,N$3,0) -> LÝ | O35: =VLOOKUP($G36,$L$5:$P$10,O$3,0) -> TOÁN | P35: =VLOOKUP($G36,$L$5:$P$10,P$3,0) -> SỬ | T35: #N/A
A36: {=IF(F36="","",SUBTOTAL(3,$F$18:F36))} -> 15 | B36: 1 | C36: 7B | D36: 29 | F36: =C36&".T" -> 7B.T | G36: TH4 | H36: 10AT | I36: =VLOOKUP($H36,$D$2:$J$13,6,0) -> Thứ Hai (22/12) | J36: =VLOOKUP($H36,$D$2:$J$13,7,0) -> Thứ Ba (23/12) | K36: 29 | L36: =D36-K36 -> 0 | M36: =VLOOKUP($G36,$L$5:$P$9,M$3,0) -> VĂN | N36: =VLOOKUP($G36,$L$5:$P$9,N$3,0) -> LÝ | O36: =VLOOKUP($G36,$L$5:$P$9,O$3,0) -> TOÁN | P36: =VLOOKUP($G36,$L$5:$P$9,P$3,0) -> SỬ | Q36: =R33+1 -> 100332 | R36: =Q36+K36-1 -> 100360 | S36: TỔ HỢP 4 (10AT1,2) | T36: NGÀY THI: 22+23/12/2025
A37: {=IF(F37="","",SUBTOTAL(3,$F$18:F37))} -> 16 | B37: 2 | C37: 8B | D37: 29 | F37: =C37&".T" -> 8B.T | G37: TH4 | H37: 10AT | I37: =VLOOKUP($H37,$D$2:$J$13,6,0) -> Thứ Hai (22/12) | J37: =VLOOKUP($H37,$D$2:$J$13,7,0) -> Thứ Ba (23/12) | K37: 29 | L37: =D37-K37 -> 0 | M37: =VLOOKUP($G37,$L$5:$P$9,M$3,0) -> VĂN | N37: =VLOOKUP($G37,$L$5:$P$9,N$3,0) -> LÝ | O37: =VLOOKUP($G37,$L$5:$P$9,O$3,0) -> TOÁN | P37: =VLOOKUP($G37,$L$5:$P$9,P$3,0) -> SỬ | Q37: =Q36+K36 -> 100361 | R37: =Q37+K37-1 -> 100389 | S37: TỔ HỢP 4 (10AT1,2) | T37: NGÀY THI: 22+23/12/2025
A38: {=IF(F38="","",SUBTOTAL(3,$F$18:F38))} -> 17 | B38: 3 | C38: 9B | D38: 29 | F38: =C38&".T" -> 9B.T | G38: TH4 | H38: 10AT | I38: =VLOOKUP($H38,$D$2:$J$13,6,0) -> Thứ Hai (22/12) | J38: =VLOOKUP($H38,$D$2:$J$13,7,0) -> Thứ Ba (23/12) | K38: 29 | L38: =D38-K38 -> 0 | M38: =VLOOKUP($G38,$L$5:$P$9,M$3,0) -> VĂN | N38: =VLOOKUP($G38,$L$5:$P$9,N$3,0) -> LÝ | O38: =VLOOKUP($G38,$L$5:$P$9,O$3,0) -> TOÁN | P38: =VLOOKUP($G38,$L$5:$P$9,P$3,0) -> SỬ | Q38: =Q37+K37 -> 100390 | R38: =Q38+K38-1 -> 100418 | S38: TỔ HỢP 4 (10AT1,2) | T38: NGÀY THI: 22+23/12/2025
A39: {=IF(F39="","",SUBTOTAL(3,$F$18:F39))} | B39: KHỐI 11AS | C39: 5 phòng | D39: 142 | T39: #N/A
A40: {=IF(F40="","",SUBTOTAL(3,$F$18:F40))} | B40: TỔ HỢP 4 (11AS1,2,3) | D40: 142 | M40: =VLOOKUP($G41,$L$5:$P$10,M$3,0) -> VĂN | N40: SINH | O40: =VLOOKUP($G41,$L$5:$P$10,O$3,0) -> TOÁN | P40: =VLOOKUP($G41,$L$5:$P$10,P$3,0) -> SỬ | T40: #N/A
...

Sheet 4_Sơ đồ mẫu
A1: =VLOOKUP($AC1,'1_Coppy_Tke Pthi dan'!$A$18:$S$165,19,0) -> TỔ HỢP 2 (10AS1,2) | H1: =A1 -> TỔ HỢP 2 (10AS1,2) | O1: =H1 -> TỔ HỢP 2 (10AS1,2) | V1: =O1 -> TỔ HỢP 2 (10AS1,2) | AC1: =$AH$1 -> 1 | AD1: =VLOOKUP($AC1,'1_Coppy_Tke Pthi dan'!$A$18:$S$165,7,0) -> TH2 | AE1: =VLOOKUP($AC1,'1_Coppy_Tke Pthi dan'!$A$18:$S$165,3,0) -> 1A | AF1: 22 | AH1: 1
A2: Sơ đồ chỗ ngồi | H2: =$A$2 -> Sơ đồ chỗ ngồi | O2: =$A$2 -> Sơ đồ chỗ ngồi | V2: =$A$2 -> Sơ đồ chỗ ngồi | AC2: Mã | AD2: Tổ hợp | AE2: C.thức | AF2: SL | AH2: =AH1+1 -> 2
A3: =VLOOKUP($AC1,'1_Coppy_Tke Pthi dan'!$A$18:$S$165,13,0) -> VĂN | E3: ="P. "&$AE1 -> P. 1A | H3: =VLOOKUP($AC1,'1_Coppy_Tke Pthi dan'!$A$18:$S$165,14,0) -> HÓA | L3: =E3 -> P. 1A | O3: =VLOOKUP($AC1,'1_Coppy_Tke Pthi dan'!$A$18:$S$165,15,0) -> TOÁN | S3: =L3 -> P. 1A | V3: =VLOOKUP($AC1,'1_Coppy_Tke Pthi dan'!$A$18:$S$165,16,0) -> SỬ | Z3: =S3 -> P. 1A | AC3: 100001 | AD3: 100022 | AH3: =AH2+1 -> 3
A4: Bàn Giáo viên | H4: Bàn Giáo viên | O4: Bàn Giáo viên | V4: Bàn Giáo viên | AH4: =AH3+1 -> 4
AH5: =AH4+1 -> 5
A6: =VLOOKUP($AC1,'1_Coppy_Tke Pthi dan'!$A$18:$S$165,17,0) -> 100001 | B6: =A6+5 -> 100006 | D6: =A6+11 -> 100012 | E6: =A6+17 -> 100018 | H6: =L6+17 -> 100018 | I6: =L6+11 -> 100012 | K6: =L6+5 -> 100006 | L6: =VLOOKUP($AC1,'1_Coppy_Tke Pthi dan'!$A$18:$S$165,17,0) -> 100001 | O6: =AD3 -> 100022 | P6: =O6-1 -> 100021 | R6: =P6-1 -> 100020 | S6: =R6-1 -> 100019 | V6: =W6-1 -> 100019 | W6: =Y6-1 -> 100020 | Y6: =Z6-1 -> 100021 | Z6: =AD3 -> 100022 | AH6: =AH5+1 -> 6
A7: =A6+1 -> 100002 | B7: =A7+5 -> 100007 | D7: =A7+11 -> 100013 | E7: =A7+17 -> 100019 | H7: =L7+17 -> 100019 | I7: =L7+11 -> 100013 | K7: =L7+5 -> 100007 | L7: =L6+1 -> 100002 | O7: =P7-1 -> 100015 | P7: =R7-1 -> 100016 | R7: =S7-1 -> 100017 | S7: =S6-1 -> 100018 | V7: =V6-1 -> 100018 | W7: =V7-1 -> 100017 | Y7: =W7-1 -> 100016 | Z7: =Y7-1 -> 100015 | AH7: =AH6+1 -> 7
A8: =A7+1 -> 100003 | B8: =A8+5 -> 100008 | D8: =A8+11 -> 100014 | E8: =A8+17 -> 100020 | H8: =L8+17 -> 100020 | I8: =L8+11 -> 100014 | K8: =L8+5 -> 100008 | L8: =L7+1 -> 100003 | O8: =O7-1 -> 100014 | P8: =O8-1 -> 100013 | R8: =P8-1 -> 100012 | S8: =R8-1 -> 100011 | V8: =W8-1 -> 100011 | W8: =Y8-1 -> 100012 | Y8: =Z8-1 -> 100013 | Z8: =Z7-1 -> 100014 | AH8: =AH7+1 -> 8
A9: =A8+1 -> 100004 | B9: =A9+5 -> 100009 | D9: =A9+11 -> 100015 | E9: =A9+17 -> 100021 | H9: =L9+17 -> 100021 | I9: =L9+11 -> 100015 | K9: =L9+5 -> 100009 | L9: =L8+1 -> 100004 | O9: =P9-1 -> 100007 | P9: =R9-1 -> 100008 | R9: =S9-1 -> 100009 | S9: =S8-1 -> 100010 | V9: =V8-1 -> 100010 | W9: =V9-1 -> 100009 | Y9: =W9-1 -> 100008 | Z9: =Y9-1 -> 100007 | AH9: =AH8+1 -> 9
A10: =A9+1 -> 100005 | B10: =A10+5 -> 100010 | D10: =A10+11 -> 100016 | E10: =A10+17 -> 100022 | H10: =L10+17 -> 100022 | I10: =L10+11 -> 100016 | K10: =L10+5 -> 100010 | L10: =L9+1 -> 100005 | O10: =O9-1 -> 100006 | P10: =O10-1 -> 100005 | R10: =P10-1 -> 100004 | S10: =R10-1 -> 100003 | V10: =W10-1 -> 100003 | W10: =Y10-1 -> 100004 | Y10: =Z10-1 -> 100005 | Z10: =Z9-1 -> 100006 | AH10: =AH9+1 -> 10
B11: =B10+1 -> 100011 | D11: =D10+1 -> 100017 | I11: =I10+1 -> 100017 | K11: =K10+1 -> 100011 | P11: =R11-1 -> 100001 | R11: =S10-1 -> 100002 | W11: =V10-1 -> 100002 | Y11: =W11-1 -> 100001 | AH11: =AH10+1 -> 11
AH12: =AH11+1 -> 12
AH15: =AH12+1 -> 13
